Workbook

Sheet 현황판
A1: 핏크닉 강사 모집 현황판
A2: ="기준일: "&TEXT(TODAY(),"yyyy년 mm월 dd일")&" — 강사모집 탭 상태 자동 반영" -> 기준일: 2026년 04월 01일 — 강사모집 탭 상태 자동 반영
B3: 발송 완료 | D3: 응답 | F3: 미팅 | H3: 계약
B4: =COUNTIF('강사모집'!B2:B996,"진행 중")+COUNTIF('강사모집'!B2:B996,"계약 완료") -> 283 | D4: =COUNTIF('진행중'!X2:X1000,"진행 중")+COUNTIF('진행중'!X2:X1000,"미팅 완료")+COUNTIF('진행중'!X2:X1000,"계약 완료") -> 9 | F4: =COUNTIF('진행중'!X2:X1000,"미팅 완료")+COUNTIF('진행중'!X2:X1000,"계약 완료") -> 8 | H4: =COUNTIF('강사모집'!B2:B996,"계약 완료") -> 8
B6: 응답률 | D6: 미팅 전환율 | F6: 계약 전환율 | H6: 발송 대비 계약
B7: =IFERROR(D4/B4,0) -> 0.03180212 | D7: =IFERROR(F4/D4,0) -> 0.88888889 | F7: =IFERROR(H4/F4,0) -> 1 | H7: =IFERROR(H4/B4,0) -> 0.028268551
B9: 상태별 현황 | F9: 본부장님 확인 필요
B10: 상태 | C10: 인원 | D10: 비율 | F10: 컨펌 대기 중
B11: 미검토 | C11: =COUNTIF('강사모집'!B2:B996,"미검토") -> 15 | D11: =IFERROR(C11/SUM(C$11:C$18),0) -> 0.018495684 | F11: =COUNTIF('강사모집'!B2:B996,"컨펌 필요") -> 3
B12: 컨펌 필요 | C12: =COUNTIF('강사모집'!B2:B996,"컨펌 필요") -> 3 | D12: =IFERROR(C12/SUM(C$11:C$18),0) -> 0.0036991369 | F12: 명이 컨펌을 기다리고 있어요
B13: 발송 예정 | C13: =COUNTIF('강사모집'!B2:B996,"발송 예정") -> 0 | D13: =IFERROR(C13/SUM(C$11:C$18),0) -> 0 | F13: 강사모집 탭에서 "컨펌 필요" 선택 시 자동 반영
B14: 진행 중 | C14: =COUNTIF('강사모집'!B2:B996,"진행 중") -> 275 | D14: =IFERROR(C14/SUM(C$11:C$18),0) -> 0.33908755
B15: 계약 완료 | C15: =COUNTIF('강사모집'!B2:B996,"계약 완료") -> 8 | D15: =IFERROR(C15/SUM(C$11:C$18),0) -> 0.009864365 | F15: 전체 강사 후보
B16: 제외 | C16: =COUNTIF('강사모집'!B2:B996,"제외") -> 485 | D16: =IFERROR(C16/SUM(C$11:C$18),0) -> 0.59802713 | F16: =COUNTA('강사모집'!F2:F996) -> 810
B17: 보류 | C17: =COUNTIF('강사모집'!B2:B996,"보류") -> 19 | D17: =IFERROR(C17/SUM(C$11:C$18),0) -> 0.023427867
B18: 거절 | C18: =COUNTIF('강사모집'!B2:B996,"거절") -> 6 | D18: =IFERROR(C18/SUM(C$11:C$18),0) -> 0.0073982737
B20: 인바운드 지원서 현황
B21: 폼 | C21: 미확인 | D21: 확인완료
B22: 핏크닉메타 | C22: =IFERROR(COUNTIF('핏크닉메타'!N4:N500,"미확인")+COUNTBLANK('핏크닉메타'!N4:N500)-COUNTBLANK('핏크닉메타'!A4:A500),0) -> -83 | D22: =IFERROR(COUNTIF('핏크닉메타'!N4:N500,"확인완료"),0) -> 83
B23: 핏크닉홈페이지 | C23: =IFERROR(COUNTIF('핏크닉홈'!M4:M500,"미확인")+COUNTBLANK('핏크닉홈'!M4:M500)-COUNTBLANK('핏크닉홈'!A4:A500),0) -> 1 | D23: =IFERROR(COUNTIF('핏크닉홈'!M4:M500,"확인완료"),0) -> 60
B24: 머니업홈페이지 | C24: =IFERROR(COUNTIF('머니업홈'!M4:M500,"미확인")+COUNTBLANK('머니업홈'!M4:M500)-COUNTBLANK('머니업홈'!A4:A500),0) -> 3 | D24: =IFERROR(COUNTIF('머니업홈'!M4:M500,"확인완료"),0) -> 32
B25: 핏크닉카페 | C25: =IFERROR(COUNTIF('핏크닉카'!L4:L500,"미확인")+COUNTBLANK('핏크닉카'!L4:L500)-COUNTBLANK('핏크닉카'!A4:A500),0) -> 2 | D25: =IFERROR(COUNTIF('핏크닉카'!L4:L500,"확인완료"),0) -> 2
B26: 머니업카페 | C26: =IFERROR(COUNTIF('머니업카'!L4:L500,"미확인")+COUNTBLANK('머니업카'!L4:L500)-COUNTBLANK('머니업카'!A4:A500),0) -> 1 | D26: =IFERROR(COUNTIF('머니업카'!L4:L500,"확인완료"),0) -> 2
B27: 합계 | C27: =SUM(C22:C26) -> -76 | D27: =SUM(D22:D26) -> 179

Sheet 강사모집
A1: ㅜ | B1: 상태 | C1: 제외/보류 사유 | D1: 분야 | E1: 담당자 | F1: 강사 이름 | G1: 참조 링크 | H1: 강의 이력 여부 | I1: 강의 플랫폼 | J1: 유튜브 | K1: 인스타 | L1: 이메일 (링크X 인스타 없는 강사만!) | M1: 비고 | O1: 발송채널 | P1: DM | Q1: 메일 | R1: 1차 발송일 | S1: 1차 결과 | T1: 2차 발송일 | U1: 2차 결과 | V1: 3차 발송일 | W1: 3차 결과 | X1: 최종 상태 | Y1: 미팅 메모 | Z1: 비고
B2: 제외 | C2: 타이탄/앤잡/코주부 강사 | D2: 예시) 삼삼엠투 | E2: 김상원 | F2: 부자꿈틀 | G2: https://www.youtube.com/watch?v=G6cGTwMHq-U | H2: O | I2: 개인 컨설팅 | J2: 부자꿈틀 - 공간대여 여성수 | K2: https://www.instagram.com/booggum/ | O2: =IF(AND(P2=1,Q2=0),"DM",IF(AND(P2=0,Q2=1),"이메일",IF(AND(P2=1,Q2=1),"DM+이메일",""))) | P2: 0 | Q2: 0
B3: 제외 | D3: 사업 컨설팅 | E3: 김지상 | F3: 사업왕 심길후 | G3: https://cafe.naver.com/wwwxodls77/505655 | H3: O | I3: 개인 및 단체 컨설팅, 클래스유 | J3: 사업의 참견 | K3: https://www.instagram.com/simgilhu/ | M3: 아웃- 카페 7만 | O3: =IF(AND(P3=1,Q3=0),"DM",IF(AND(P3=0,Q3=1),"이메일",IF(AND(P3=1,Q3=1),"DM+이메일",""))) | P3: 0 | Q3: 0
B4: 제외 | D4: 영상제작(릴스) | E4: 김서윤 | F4: 영꿀 롱제이 김진아 | G4: https://mkt.taling.me/mkt-vod/reels_1?utm_source=onsight&utm_medium=organic&utm_campaign=reels_purchase&utm_content=homebanner&utm_term=%7Bquery%7D&fbclid=PAY2xjawHR75hleHRuA2FlbQIxMAABpjgESBrwT5IueDKHl99Tf8PGbD_BOSSV71p5Jgi_phe872WvO0GwtV7qQg_aem_K2jZnB_9XzqIpIVsZSjnHw | H4: O | I4: 오프라인 강연 및 탈잉 홈페이지 | J4: https://youtu.be/D-beesDeTC8?si=OHlvnOAFr9DLPQPS | K4: https://www.instagram.com/ggultip_longj?igsh=cjU4YzIxN20wczl5 | M4: 제안아웃-(최근탈잉런칭이유) | O4: =IF(AND(P4=1,Q4=0),"DM",IF(AND(P4=0,Q4=1),"이메일",IF(AND(P4=1,Q4=1),"DM+이메일",""))) | P4: 0 | Q4: 0
B5: 제외 | D5: 에어비엔비 | E5: 정승요 | F5: 부자꿈틀 | H5: O | I5: 업음 | M5: 새로운 사이트에서 하기로함 | O5: =IF(AND(P5=1,Q5=0),"DM",IF(AND(P5=0,Q5=1),"이메일",IF(AND(P5=1,Q5=1),"DM+이메일",""))) | P5: 0 | Q5: 0
B6: 계약 완료 | D6: 해외구매대행 | E6: 정세희 | F6: 핫뜨 | G6: https://www.youtube.com/watch?v=elhxzHXqGRw | H6: O | I6: 개인 컨설팅 | J6: https://www.youtube.com/@hotdd2030/shorts | M6: 연락해봄 (기다림) | O6: =IF(AND(P6=1,Q6=0),"DM",IF(AND(P6=0,Q6=1),"이메일",IF(AND(P6=1,Q6=1),"DM+이메일",""))) | P6: 0 | Q6: 0
B7: 계약 완료 | D7: 구글 온라인 자동화 수입 | E7: 김서윤 | F7: 선한부자 오가닉 | G7: https://class101.net/ko/products/61f68f1cf3a2e1000d780fda | H7: ㅇ | I7: 클래스 101 | J7: https://youtube.com/channel/UChIn7_WTuf2NcRBCvXgv2EA?si=HbthIS3jUHZtK_kV | K7: https://www.instagram.com/positiverich_organic?igsh=MXQwcmx4NDhmc2FhZQ== | M7: 연락해봄 (기다림) | O7: =IF(AND(P7=1,Q7=0),"DM",IF(AND(P7=0,Q7=1),"이메일",IF(AND(P7=1,Q7=1),"DM+이메일",""))) | P7: 0 | Q7: 0
B8: 계약 완료 | G8: https://weolbu.com/product?displaySeq=1002&utm_source=creator&utm_medium=affiliate&utm_campaign=class_organic&utm_content=traffic_creator_24&utm_term=youtube&fbclid=PAY2xjawHdzNVleHRuA2FlbQIxMAABppHOhAX0rOzfKK5kSFLSzIEFFXYHUBaYSTLJ-TOgoP6cQLcCGS8H_a_Igg_aem_-T_zv0UGunC1YUFbHudqEg | I8: 월부닷컴 | O8: =IF(AND(P8=1,Q8=0),"DM",IF(AND(P8=0,Q8=1),"이메일",IF(AND(P8=1,Q8=1),"DM+이메일",""))) | P8: 0 | Q8: 0
B9: 계약 완료 | D9: AI 상세페이지 | E9: 김상원 | F9: 디선제압 | G9: https://www.youtube.com/@%EB%94%94%EC%84%A0%EC%A0%9C%EC%95%95 | H9: X | M9: open.kakao.com/o/gWMf3K3g | O9: =IF(AND(P9=1,Q9=0),"DM",IF(AND(P9=0,Q9=1),"이메일",IF(AND(P9=1,Q9=1),"DM+이메일",""))) | P9: 0 | Q9: 0
B10: 계약 완료 | D10: 상세페이지 기획 (AI) | E10: 정승희 | F10: 페이지부스터 | G10: 유튜브 | H10: X | J10: 유튜브 | M10: 이메일 | O10: =IF(AND(P10=1,Q10=0),"DM",IF(AND(P10=0,Q10=1),"이메일",IF(AND(P10=1,Q10=1),"DM+이메일",""))) | P10: 0 | Q10: 0
B11: 계약 완료 | D11: AI 유튜브 수익화 | E11: 윤원경 | F11: 지인옥 (작가) | G11: 블로그 | H11: ? | I11: 런칭하려고 웨비나받음 | J11: http://www.youtube.com/@%EC%A7%80%EC%9D%B8%EC%98%A5 | K11: https://www.instagram.com/jee_writer?igsh=bHppbnV6dGwybm05 | L11: https://jeeinok.com/ai-youtube-landing | O11: =IF(AND(P11=1,Q11=0),"DM",IF(AND(P11=0,Q11=1),"이메일",IF(AND(P11=1,Q11=1),"DM+이메일",""))) | P11: 0 | Q11: 0
B12: 계약 완료 | D12: AI 숏츠 | E12: 국선우 | F12: 제이 온리 | G12: 인스타 | H12: o | I12: 개인 | K12: https://www.instagram.com/j_only8?utm_source=ig_web_button_share_sheet&igsh=cTJwMG9yZGpoMDh0 | O12: =IF(AND(P12=1,Q12=0),"DM",IF(AND(P12=0,Q12=1),"이메일",IF(AND(P12=1,Q12=1),"DM+이메일",""))) | P12: 0 | Q12: 0
B13: 계약 완료 | D13: AI 상세페이지 | E13: 정승희 | F13: 이지디자인 | G13: 유튜브 | H13: O | I13: 패스트 캠퍼스 | J13: https://www.youtube.com/@EasyDesign_ED/videos | K13: https://www.instagram.com/easy_design.ed/ | L13: easydesign502@gmail.com | M13: 누적 수강생 8,000명 | O13: =IF(AND(P13=1,Q13=0),"DM",IF(AND(P13=0,Q13=1),"이메일",IF(AND(P13=1,Q13=1),"DM+이메일",""))) | P13: 0 | Q13: 0
B14: 진행 중 | D14: 티스토리블로그, 구글애드센스 | E14: 김서윤 | F14: 리뷰요정리남 | G14: https://class101.net/ko/products/5dcd2c1f0bdefc4e498af73e | H14: O | I14: 클래스 101 | J14: https://www.youtube.com/channel/UCRx7_s9Mvw9j2mLSaj6X70g | K14: https://www.instagram.com/reviewyojung/# | L14: reviewyojung@naver.com | O14: =IF(AND(P14=1,Q14=0),"DM",IF(AND(P14=0,Q14=1),"이메일",IF(AND(P14=1,Q14=1),"DM+이메일",""))) -> DM+이메일 | P14: 1 | Q14: 1 | T14: 46108 | U14: 무응답
B15: 제외 | D15: 영상제작(릴스) | E15: 김지상 | F15: 릴스해커 | G15: https://www.reelshacker.co.kr/ | H15: O | I15: 개인 및 단체 컨설팅, 온라인 vod | J15: https://www.youtube.com/@reels_hacker_/videos | K15: https://www.instagram.com/reels___hacker/ | O15: =IF(AND(P15=1,Q15=0),"DM",IF(AND(P15=0,Q15=1),"이메일",IF(AND(P15=1,Q15=1),"DM+이메일",""))) | P15: 0 | Q15: 0
B16: 제외 | D16: 쿠팡 로켓그로스 | E16: 장찬민 | F16: 새끼공룡 모건 | G16: https://www.youtube.com/@morgan-c1c | H16: X | I16: 없음 | M16: 연락해봄 (기다림) | O16: =IF(AND(P16=1,Q16=0),"DM",IF(AND(P16=0,Q16=1),"이메일",IF(AND(P16=1,Q16=1),"DM+이메일",""))) | P16: 0 | Q16: 0
B17: 제외 | D17: 현금 에어드랍 | E17: 김상원 | F17: 머니메이커 | M17: 댓글써봄(기다림) | O17: =IF(AND(P17=1,Q17=0),"DM",IF(AND(P17=0,Q17=1),"이메일",IF(AND(P17=1,Q17=1),"DM+이메일",""))) | P17: 0 | Q17: 0
B18: 제외 | C18: 타이탄/앤잡/코주부 강사 | D18: 에어비엔비 | E18: 정승요 | F18: 최사장 | H18: O | O18: =IF(AND(P18=1,Q18=0),"DM",IF(AND(P18=0,Q18=1),"이메일",IF(AND(P18=1,Q18=1),"DM+이메일",""))) | P18: 0 | Q18: 0
B19: 제외 | D19: 소셜링 | E19: 정세희 | F19: 유리마제 | G19: https://millmus.com/lecture/detail/129 | H19: O | I19: 개인 컨설팅, 밀머스 | J19: 유리마제 : 재밌게 돈벌기 달인 | K19: https://www.instagram.com/_yurimage/ | M19: 댓글써봄(기다림) | O19: =IF(AND(P19=1,Q19=0),"DM",IF(AND(P19=0,Q19=1),"이메일",IF(AND(P19=1,Q19=1),"DM+이메일",""))) | P19: 0 | Q19: 0
B20: 제외 | D20: 비트코인 | E20: 김서윤 | F20: 돈복남 | G20: https://youtu.be/eVSkY_cd0D8?si=MfREs5Z55theFrzd | H20: O | I20: 자체 오프라인 강의 및 단체 컨설팅(디스코드, 유튜브 멤버십) | J20: https://www.youtube.com/@TV-kc6ue | K20: https://www.instagram.com/donboknam_real/?hl=ko | M20: 이미 타이탄에서함 | O20: =IF(AND(P20=1,Q20=0),"DM",IF(AND(P20=0,Q20=1),"이메일",IF(AND(P20=1,Q20=1),"DM+이메일",""))) | P20: 0 | Q20: 0
B21: 제외 | D21: 꽃 위탁판매 | E21: 김서윤 | F21: 김윤화 | G21: https://youtu.be/cd9eRQGjfqo?si=wR_LhTKqwja7m9wF | H21: O | I21: 개인 | J21: https://www.youtube.com/channel/UCSiBYGuWPLiuqLneE6iAtdg | M21: 연락해봄 (기다림) | O21: =IF(AND(P21=1,Q21=0),"DM",IF(AND(P21=0,Q21=1),"이메일",IF(AND(P21=1,Q21=1),"DM+이메일",""))) | P21: 0 | Q21: 0
B22: 제외 | D22: 앱테크 수익화 | E22: 장찬민 | F22: 재택알바남 | G22: https://onemorething9196.imweb.me/home | H22: O | I22: 원모어띵 | J22: https://www.youtube.com/@homejobman | M22: 이상함 | O22: =IF(AND(P22=1,Q22=0),"DM",IF(AND(P22=0,Q22=1),"이메일",IF(AND(P22=1,Q22=1),"DM+이메일",""))) | P22: 0 | Q22: 0
B23: 진행 중 | D23: 생성형 AI | E23: 김지상 | F23: 챗GPT강사 이도혜 | H23: O | I23: 개인 | J23: https://www.youtube.com/@chatgpt.114/videos | K23: https://www.instagram.com/tiffany_story__ | L23: dohye.edu@gmail.com | M23: 너무 많은곳을하고있음 | O23: =IF(AND(P23=1,Q23=0),"DM",IF(AND(P23=0,Q23=1),"이메일",IF(AND(P23=1,Q23=1),"DM+이메일",""))) -> DM+이메일 | P23: 1 | Q23: 1 | T23: 46108 | U23: 무응답
B24: 제외 | D24: 공동구매 | E24: 김상원 | F24: 저스트고 | G24: https://www.youtube.com/watch?v=d5vwNuPq1Cw | H24: O | I24: https://justgo.liveklass.com/ | J24: http://www.youtube.com/@justgo7994 | K24: http://instagram.com/justgo_kms | M24: 연락해봄 (기다림) | O24: =IF(AND(P24=1,Q24=0),"DM",IF(AND(P24=0,Q24=1),"이메일",IF(AND(P24=1,Q24=1),"DM+이메일",""))) | P24: 0 | Q24: 0
B25: 제외 | D25: 나스닥(주식) | E25: 김상원 | F25: 김직선 | G25: https://www.youtube.com/watch?v=y6Eng4FKyU0 | H25: O | I25: https://bit.ly/3NT9R93 | J25: http://www.youtube.com/@ndaqtrader | M25: 한트협인가 하는곳이 너무잘되어있음 | O25: =IF(AND(P25=1,Q25=0),"DM",IF(AND(P25=0,Q25=1),"이메일",IF(AND(P25=1,Q25=1),"DM+이메일",""))) | P25: 0 | Q25: 0
B26: 제외 | D26: 유튜브 브랜딩 | E26: 김상원 | F26: 커밍쑨 | G26: https://www.youtube.com/watch?v=kuUlab1qHEc | H26: O | I26: https://psmakers.liveklass.com/classes/218286 | J26: https://www.youtube.com/@%EC%BB%A4%EB%B0%8D%EC%8F%9C | O26: =IF(AND(P26=1,Q26=0),"DM",IF(AND(P26=0,Q26=1),"이메일",IF(AND(P26=1,Q26=1),"DM+이메일",""))) | P26: 0 | Q26: 0
B27: 제외 | D27: 유튜브 쇼핑 | E27: 김서윤 | F27: 부업부부 | G27: https://youtu.be/ddqetdI4RYI?si=wz3e688OmUp7U4Xb | H27: O | I27: 부업부부 홈페이지 | J27: https://youtube.com/channel/UCssMAfwEpQF0GZ8V0a57vuQ?si=koHplR_ofsIRDdk9 | K27: X | M27: 메일해봄(기다림) | O27: =IF(AND(P27=1,Q27=0),"DM",IF(AND(P27=0,Q27=1),"이메일",IF(AND(P27=1,Q27=1),"DM+이메일",""))) | P27: 0 | Q27: 0
B28: 제외 | D28: 학교장터 S2B | E28: 김서윤 | F28: 돈기부여 | G28: https://youtu.be/UFTP-Yl2vuc?si=KmnzMpvd89P0hYP- | H28: O | I28: 공개적으로 하지는 않는 것 같음, 구글폼 신청자에게만 개별 강의 안내 구글폼링크 : bit.ly/3ImW20a 강의문의 연락처 : 010-5385-9395 | J28: https://youtube.com/channel/UCbO7ae8WmgGuK9-d6OkQ6JQ?si=89eby5Tl0EFdDSTn | O28: =IF(AND(P28=1,Q28=0),"DM",IF(AND(P28=0,Q28=1),"이메일",IF(AND(P28=1,Q28=1),"DM+이메일",""))) | P28: 0 | Q28: 0
B29: 진행 중 | D29: 해외 및 국내 구매 대행 | E29: 정세희 | F29: 부추경자 | G29: 부추경자 블로그 https://www.youtube.com/watch?v=6xMbPBWr_AU | H29: O | I29: 현) 개인 컨설팅 전) 타이탄 수강생, 초청 강사 | J29: https://www.youtube.com/channel/UCsXCQkVgOZMwlaXqVr3rpjQ | K29: https://www.instagram.com/buchugj/ | L29: darmvit@naver.com | O29: =IF(AND(P29=1,Q29=0),"DM",IF(AND(P29=0,Q29=1),"이메일",IF(AND(P29=1,Q29=1),"DM+이메일",""))) -> DM+이메일 | P29: 1 | Q29: 1 | T29: 46108 | V29: 2026.04.01
B30: 제외 | D30: 생성형 AI | E30: 정세희 | F30: AIX 에익스 (나민수) & 윤권 | G30: 나민수 - 저스트두잇클럽 | H30: O | I30: 개인 컨설팅, 오프라인 기업 강연 | K30: https://www.instagram.com/naminsoo_ai/?utm_source=ig_web_button_share_sheet&igsh=ZDNlZDc0MzIxNw%3D%3D# | O30: =IF(AND(P30=1,Q30=0),"DM",IF(AND(P30=0,Q30=1),"이메일",IF(AND(P30=1,Q30=1),"DM+이메일",""))) | P30: 0 | Q30: 0
B31: 제외 | G31: 나민수 & 윤권 - AI 스타트 클럽 | K31: https://www.instagram.com/yoonkwon_ai/?igsh=dmN0NjBlaGppamts# | O31: =IF(AND(P31=1,Q31=0),"DM",IF(AND(P31=0,Q31=1),"이메일",IF(AND(P31=1,Q31=1),"DM+이메일",""))) | P31: 0 | Q31: 0
B32: 제외 | D32: 구글 에드센스 | E32: 김지상 | F32: 저스트액션 | G32: https://www.youtube.com/@JUSTACTION50/videos | H32: O | I32: https://justaction.liveklass.com/ | J32: https://www.youtube.com/@JUSTACTION50/videos | K32: X | M32: 메일해봄(기다림) | O32: =IF(AND(P32=1,Q32=0),"DM",IF(AND(P32=0,Q32=1),"이메일",IF(AND(P32=1,Q32=1),"DM+이메일",""))) | P32: 0 | Q32: 0
B33: 제외 | D33: 생성형 AI | E33: 정세희 | F33: 이너리드 | G33: https://litt.ly/infj_aibro | H33: O | I33: 개인 컨설팅 | J33: https://youtube.com/@innerlead?si=UcrMAF02k0R8nNbP | K33: X | O33: =IF(AND(P33=1,Q33=0),"DM",IF(AND(P33=0,Q33=1),"이메일",IF(AND(P33=1,Q33=1),"DM+이메일",""))) | P33: 0 | Q33: 0
B34: 제외 | D34: 쿠팡, 스마트스토어 | E34: 정세희 | F34: 돈버는하마 | G34: https://m.cafe.naver.com/ca-fe/web/cafes/gimpophone/articles/10574?useCafeId=false&tc | H34: O | I34: 개인 컨설팅 | J34: https://youtube.com/@makingmoneyhippo?si=9JaabwWaGZiO5kFS | K34: https://www.instagram.com/makingmoneyhippo?igsh=ZDhqNWRzNXFqeDMz | O34: =IF(AND(P34=1,Q34=0),"DM",IF(AND(P34=0,Q34=1),"이메일",IF(AND(P34=1,Q34=1),"DM+이메일",""))) | P34: 0 | Q34: 0
B35: 제외 | D35: 인스타툰 | E35: 김지상 | F35: 소금툰 | G35: https://fastcampus.co.kr/dgn_online_cd | H35: O | I35: 패스트 캠퍼스 | J35: X | K35: https://www.instagram.com/sogeumtoon/ | O35: =IF(AND(P35=1,Q35=0),"DM",IF(AND(P35=0,Q35=1),"이메일",IF(AND(P35=1,Q35=1),"DM+이메일",""))) | P35: 0 | Q35: 0
B36: 제외 | D36: 부동산 투자 | E36: 김지상 | F36: 월세여왕 리나쌤 | G36: https://linaedu.modoo.at/ | H36: O | I36: 개인 강의 | J36: https://www.youtube.com/@lina_only_one | K36: https://www.instagram.com/lina_only_one/ | O36: =IF(AND(P36=1,Q36=0),"DM",IF(AND(P36=0,Q36=1),"이메일",IF(AND(P36=1,Q36=1),"DM+이메일",""))) | P36: 0 | Q36: 0
B37: 제외 | D37: 구매대행 | E37: 김지상 | F37: 셀벤져스 로라 | G37: https://cafe.naver.com/cellaravengers/30491 | H37: O | I37: 강의 | J37: https://www.youtube.com/@sell_vengers/community | K37: https://www.instagram.com/sellvengers_rora/ | O37: =IF(AND(P37=1,Q37=0),"DM",IF(AND(P37=0,Q37=1),"이메일",IF(AND(P37=1,Q37=1),"DM+이메일",""))) | P37: 0 | Q37: 0
B38: 제외 | D38: 디자인 수익화 | E38: 김지상 | F38: 혜다나다 | G38: https://litt.ly/hyeda | H38: O | I38: 전자책 | J38: 로고사업가혜다 | K38: https://www.instagram.com/hyeda.nada/ | O38: =IF(AND(P38=1,Q38=0),"DM",IF(AND(P38=0,Q38=1),"이메일",IF(AND(P38=1,Q38=1),"DM+이메일",""))) | P38: 0 | Q38: 0
B39: 제외 | D39: AI 홈페이지 | E39: 이해수 | F39: 누끼토끼 | G39: https://nookitokki.co.kr/ | H39: O | I39: 개인 강의 | J39: https://www.youtube.com/@nookitokki | K39: https://www.instagram.com/nookitokki/ | O39: =IF(AND(P39=1,Q39=0),"DM",IF(AND(P39=0,Q39=1),"이메일",IF(AND(P39=1,Q39=1),"DM+이메일",""))) | P39: 0 | Q39: 0
B40: 제외 | D40: 라이브 커머스 | E40: 김지상 | F40: 러브미겸 황나겸 | G40: 링크트리 | H40: O | I40: 개인 강의 | J40: https://www.youtube.com/@luvme_gyeom | K40: https://www.instagram.com/luvme.gyeom/ | O40: =IF(AND(P40=1,Q40=0),"DM",IF(AND(P40=0,Q40=1),"이메일",IF(AND(P40=1,Q40=1),"DM+이메일",""))) | P40: 0 | Q40: 0
...

Sheet 콘텐츠팀 개별 컨택
A1: No. | B1: 상태 | C1: 분야 | E1: 강사명 | F1: 유튜브 | G1: 인스타 | H1: 이메일 | J1: 발송채널 | K1: DM | L1: 이메일 | M1: 1차발송일 | N1: 1차 결과 | O1: 2차 발송일 | P1: 2차 결과 | Q1: 3차 발송일 | R1: 3차 결과 | S1: 최종상태 | T1: 미팅메모 | U1: 비고
A2: {=IF(B2:B988<>"", ROW(B2:B988)-1, "")} -> 1 | B2: 진행 중 | C2: 플레이리스트 | D2: 정세희 | E2: 드루와자기 | F2: https://www.youtube.com/channel/UC3sZdDroiHtKYYdGTIhtCeA | H2: asoda98@nate.com | I2: 연락해봄 (기다림) | K2: 0 | L2: 1 | M2: 46108 | N2: 무응답 | O2: 2026.04.01
A3: 2 | B3: 진행 중 | C3: 플레이리스트 | D3: 김서윤 | E3: essential; | F3: https://www.youtube.com/channel/UCSGC87iX0QhnIfUOI_B_Rdg | H3: dl_essential@bugs.co.kr | I3: 연락해봄 (기다림) | K3: 0 | L3: 1 | M3: 46108 | N3: 무응답 | O3: 2026.04.01
A4: 3 | B4: 진행 중 | C4: 플레이리스트 | E4: the next SCON | F4: https://www.youtube.com/channel/UCJ9GFEhq9xCLeyIevUNEdNA | H4: thenextscon@gmail.com | K4: 0 | L4: 1 | M4: 46108 | N4: 무응답 | O4: 2026.04.01
A5: 4 | B5: 진행 중 | C5: 플레이리스트 | D5: 김상원 | E5: 몽렉싱피아노 MONGLAXING PIANO | F5: https://www.youtube.com/channel/UClFo7IonhjI9s_YrrhplPGA | H5: monkeybgmsound2@gmail.com | I5: open.kakao.com/o/gWMf3K3g | K5: 0 | L5: 1 | M5: 46108 | N5: 무응답 | O5: 2026.04.01
A6: 5 | B6: 진행 중 | C6: 플레이리스트 | D6: 정승희 | E6: 터닝포인트뮤직 | F6: https://www.youtube.com/channel/UC4eth-_fKt2Wg79cQqV1a8Q | H6: dkfo7869@naver.com | I6: 이메일 | K6: 0 | L6: 1 | M6: 46108 | N6: 무응답 | O6: 2026.04.01
A7: 6 | B7: 진행 중 | C7: 플레이리스트 | D7: 윤원경 | E7: 찐막 JJINMAK | F7: https://www.youtube.com/channel/UCxGyH7vzYkZwFseTUa3yZpQ | H7: seungminguy@gmail.com | K7: 0 | L7: 1 | M7: 46108 | N7: 무응답 | O7: 2026.04.01
A8: 7 | B8: 진행 중 | C8: 플레이리스트 | D8: 국선우 | E8: 남자사람친구 | F8: https://www.youtube.com/channel/UCK3aqSPhFJH2XQa2mREnSVQ | H8: itsmeboyfriend@gmail.com | K8: 0 | L8: 1 | M8: 46108 | N8: 무응답 | O8: 2026.04.01
A9: 8 | B9: 제외 | C9: 플레이리스트 | D9: 정승희 | E9: 인디인디 In The Indie | F9: https://www.youtube.com/channel/UCmBqBxouLDy3Mfu4XzESuAA | I9: 누적 수강생 8,000명 | K9: 0 | L9: 1 | M9: 46108
A10: 9 | B10: 진행 중 | C10: 플레이리스트 | D10: 김서윤 | E10: 우플리 𝐖𝐎𝐎𝐎𝐏𝐋𝐘 | F10: https://www.youtube.com/channel/UC4zMT5kGhURRcfnnFUitF2g | H10: woooply@naver.com | K10: 0 | L10: 1 | M10: 46108 | N10: 무응답 | O10: 2026.04.01
A11: 10 | B11: 진행 중 | C11: 플레이리스트 | D11: 김지상 | E11: 𝐒𝐄𝐍𝐓𝐈𝐌𝐄𝐍𝐓𝐀𝐋 𝐀𝐔𝐃𝐈𝐎 | F11: https://www.youtube.com/channel/UC4Kav4n_aYomsUQ7fZyv7ig | H11: hansung0716@gmail.com | I11: 너무 많은곳을하고있음 | K11: 0 | L11: 1 | M11: 46108 | N11: 무응답 | O11: 2026.04.01
A12: 11 | B12: 진행 중 | C12: 플레이리스트 | D12: 정세희 | E12: 감성푹 | F12: https://www.youtube.com/channel/UCFXHjmsbgmGRiUAXXyGF7Zg | H12: simada999999@gmail.com | K12: 0 | L12: 1 | M12: 46108 | N12: 무응답 | O12: 2026.04.01
A13: 12 | B13: 진행 중 | C13: 플레이리스트 | D13: 김지상 | E13: SISO Wave | F13: https://www.youtube.com/channel/UClRxY7lEeNqc6oezxGSpkKA | H13: yunsora764950@gmail.com | K13: 0 | L13: 1 | M13: 46108 | N13: 무응답 | O13: 2026.04.01
A14: 13 | B14: 진행 중 | C14: 플레이리스트 | D14: 김지상 | E14: cherry music | F14: https://www.youtube.com/channel/UCbGe5jill2XY05_TGvtKiPQ | H14: cherry_works@kakao.com | K14: 0 | L14: 1 | M14: 46108 | N14: 무응답 | O14: 2026.04.01
A15: 14 | B15: 진행 중 | C15: 플레이리스트 | D15: 김지상 | E15: 힐링음악 | F15: https://www.youtube.com/channel/UCpRqjuBMLl_6ocIKUBVRcHw | H15: healthhan119@gmail.com | K15: 0 | L15: 1 | M15: 46108 | N15: 무응답 | O15: 2026.04.01
A16: 15 | B16: 진행 중 | C16: 플레이리스트 | D16: 이해수 | E16: popment | F16: https://www.youtube.com/channel/UCZzWiPXZVug7B2K6vbKQhdw | H16: popment.official@gmail.com | K16: 0 | L16: 1 | M16: 46108 | N16: 무응답 | O16: 2026.04.01
A17: 16 | B17: 진행 중 | C17: 플레이리스트 | D17: 김은진 | E17: WRG 우리가 듣고 싶어서 연주한 playlist | F17: https://www.youtube.com/channel/UCHCyX77xqN9OVjLzMpAZvXw | H17: triojuly12@gmail.com | I17: 생성형 AI 강의 진행중 (자체 강의) | K17: 0 | L17: 1 | M17: 46108 | N17: 무응답 | O17: 2026.04.01
A18: 17 | B18: 진행 중 | C18: 플레이리스트 | D18: 김예빈 | E18: HP Music | F18: https://www.youtube.com/channel/UCIo8R3MdI7Vh2rPvaCagLeQ | H18: hpmusic.official.kr@gmail.com | K18: 0 | L18: 1 | M18: 46108 | N18: 무응답 | O18: 2026.04.01
A19: 18 | B19: 진행 중 | C19: 플레이리스트 | D19: 정세희 | E19: Objental 오브젠탈 | F19: https://www.youtube.com/channel/UCmngZzVnTQIIA9p0QaR5DBg | H19: objental@naver.com | K19: 0 | L19: 1 | M19: 46108 | N19: 무응답 | O19: 2026.04.01
A20: 19 | B20: 진행 중 | C20: 플레이리스트 | D20: 정승희 | E20: HELLO CELLO CLASSIC | F20: https://www.youtube.com/channel/UC_YH01lyI7Ivfu_TryYcbmw | H20: simplycellobgm@gmail.com | K20: 0 | L20: 1 | M20: 46108 | N20: 무응답 | O20: 2026.04.01
A21: 20 | B21: 진행 중 | C21: 플레이리스트 | D21: 정세희 | E21: onia music 오니아 뮤직 | F21: https://www.youtube.com/channel/UCWN0XUAUJiuySmhfYBBfVzQ | H21: oniabreeze@gmail.com | K21: 0 | L21: 1 | M21: 46108 | N21: 무응답 | O21: 2026.04.01
A22: 21 | B22: 진행 중 | C22: 플레이리스트 | D22: 정세희 | E22: JazzNe | F22: https://www.youtube.com/channel/UCbsHYIZwk9pZIMp53ciDjOw | H22: official@underlying.kr | K22: 0 | L22: 1 | M22: 46108 | N22: 무응답 | O22: 2026.04.01
A23: 22 | B23: 진행 중 | C23: 플레이리스트 | D23: 윤예영 | E23: mycozypop | F23: https://www.youtube.com/channel/UCYvNducBZDpqYqKLrVfuRtA | H23: iamcozypop@gmail.com | I23: VOD판매중 | K23: 0 | L23: 1 | M23: 46108 | N23: 무응답 | O23: 2026.04.01
A24: 23 | B24: 진행 중 | C24: 플레이리스트 | D24: 윤예영 | E24: ssing송 | F24: https://www.youtube.com/channel/UC3fPdi-N7Qx7Ytfw2XwRnaw | H24: singasongj47@gmail.com | I24: VOD판매중 | K24: 0 | L24: 1 | M24: 46108 | N24: 무응답 | O24: 2026.04.01
A25: 24 | B25: 진행 중 | C25: 플레이리스트 | D25: 김승철 | E25: 온에잇 𝐎𝐧 𝟖𝐢𝐠𝐡𝐭 | F25: https://www.youtube.com/channel/UCwTsxbhNyNaKTsBgjFsgGvA | H25: on8ight@gmail.com | I25: VOD 판매 중 | K25: 0 | L25: 1 | M25: 46108 | N25: 무응답 | O25: 2026.04.01
A26: 25 | B26: 진행 중 | C26: 플레이리스트 | D26: 윤예영 | E26: Song Kwangsik / 송광식 official | F26: https://www.youtube.com/channel/UCm9BsTPGsjT282jcZ6ucKRA | H26: smnow@daum.net | I26: VOD판매중,와디즈 펀딩 이력 | K26: 0 | L26: 1 | M26: 46108 | N26: 무응답 | O26: 2026.04.01
A27: 26 | B27: 진행 중 | C27: 플레이리스트 | D27: 김지상 | E27: 예오레오yeoreo | F27: https://www.youtube.com/channel/UCSUN7C7ASLG6lxNU3uGNHng | H27: yessey4135@gmail.com | K27: 0 | L27: 1 | M27: 46108 | N27: 무응답 | O27: 2026.04.01
A28: 27 | B28: 진행 중 | C28: 플레이리스트 | D28: 정승희 | E28: Breeze Mood | F28: https://www.youtube.com/channel/UCzlOuU2oqj_FCXEhy3XnvxQ | H28: breeze1mood@gmail.com | K28: 0 | L28: 1 | M28: 46108 | N28: 무응답 | O28: 2026.04.01
A29: 28 | B29: 진행 중 | C29: 플레이리스트 | D29: 이해수 | E29: 감성 저장소 | F29: https://www.youtube.com/channel/UCTieDwi-vnwxBwJGruCWvTA | H29: rkashwj@naver.com | K29: 0 | L29: 1 | M29: 46108 | N29: 무응답 | O29: 2026.04.01
A30: 29 | B30: 진행 중 | C30: 플레이리스트 | D30: 이해수 | E30: Lofi Brew | F30: https://www.youtube.com/channel/UCJg6NRMMxvEn9IOmr-rv8Ig | H30: mrpositive88@gmail.com | I30: 리틀리/ | K30: 0 | L30: 1 | M30: 46108 | N30: 무응답 | O30: 2026.04.01
A31: 30 | B31: 진행 중 | C31: 플레이리스트 | D31: 정세희 | E31: JINPLY | F31: https://www.youtube.com/channel/UCWTwVZOJBFBjDrIKGSqkrpA | H31: jinply210718@gmail.com | K31: 0 | L31: 1 | M31: 46108 | N31: 무응답 | O31: 2026.04.01
A32: 31 | B32: 진행 중 | C32: 플레이리스트 | D32: 김은진 | E32: 세레나Serena | F32: https://www.youtube.com/channel/UCg86iE8XN1-pxT-lR9BDy-g | H32: serena00800@gmail.com | I32: 요즘 것들 돈버는 이야기,일터뷰 츨연 | K32: 0 | L32: 1 | M32: 46108 | N32: 무응답 | O32: 2026.04.01
A33: 32 | B33: 제외 | C33: 플레이리스트 | D33: 김상원 | E33: apple pie | F33: https://www.youtube.com/channel/UCqI4PHxIU-Onj_YGCzTRzWA | K33: 0 | L33: 1 | M33: 46108
A34: 33 | B34: 진행 중 | C34: 플레이리스트 | D34: 장찬민 | E34: Castle Brock | F34: https://www.youtube.com/channel/UCV4k4iL-2RUNFRcvBTBe0jA | H34: jacob68.seo@gmail.com | I34: 운영하는 블로그, aion.official.ai@gmail.com | K34: 0 | L34: 1 | M34: 46108 | N34: 무응답 | O34: 2026.04.01
A35: 34 | B35: 진행 중 | C35: 플레이리스트 | D35: 원소영 | E35: Flow Music | F35: https://www.youtube.com/channel/UCC6fYTZ9AIkqNy6zYEHVwow | H35: flowmu@naver.com | I35: 네이버카페 | K35: 0 | L35: 1 | M35: 46108 | N35: 무응답 | O35: 2026.04.01
A36: 35 | B36: 진행 중 | C36: 플레이리스트 | D36: 장찬민 | E36: 우야 𝙇𝙤𝙪𝙣𝙜𝙚 | F36: https://www.youtube.com/channel/UC4p55vEp6hc1fZ-raIGQw9Q | H36: wooo00.ya.0@gmail.com | I36: ailifeinnovation@gmail.com | K36: 0 | L36: 1 | M36: 46108 | N36: 무응답 | O36: 2026.04.01
A37: 36 | B37: 진행 중 | C37: 플레이리스트 | D37: 원소영 | E37: 상어오브뮤직 | F37: https://www.youtube.com/channel/UCdlRwlBDCiAhnp2nq9QWbcw | H37: sharkofmusic@naver.com | I37: AI를 이용한 인스타툰, 블로그 글, 유투브 등 제작 | K37: 0 | L37: 1 | M37: 46108 | N37: 무응답 | O37: 2026.04.01
A38: 37 | B38: 진행 중 | C38: 플레이리스트 | D38: 이해수 | E38: 달밤의 오보에 Moonlight Oboe | F38: https://www.youtube.com/channel/UC-zkqwg5Ts1a7C0sFlokP-A | H38: moonlightoboe@gmail.com | K38: 0 | L38: 1 | M38: 46108 | N38: 무응답 | O38: 2026.04.01
A39: 38 | B39: 진행 중 | C39: 플레이리스트 | D39: 정승희 | E39: Pair Piano | F39: https://www.youtube.com/channel/UC-sGBpquT8KThBJ2ruLdg-Q | H39: pairpiano0817@gmail.com | K39: 0 | L39: 1 | M39: 46108 | N39: 무응답 | O39: 2026.04.01
A40: 39 | B40: 진행 중 | C40: 플레이리스트 | D40: 김지상 | E40: 메르헨 Marchen | F40: https://www.youtube.com/channel/UCuad7SsgU6SabSQaBY9TsFg | H40: Marchen813@gmail.com | K40: 0 | L40: 1 | M40: 46108 | N40: 무응답 | O40: 2026.04.01
...

Sheet 진행중
A1: No | B1: 상태 | D1: 분야 | F1: 강사명 | J1: 유튜브 | K1: 인스타 | L1: 이메일 / 전화번호 | N1: 발송채널 | O1: DM | P1: 이메일 | Q1: 문자 | R1: 1차발송일 | S1: 1차 결과 | T1: 2차 발송일 | U1: 2차 결과 | V1: 3차 발송일 | W1: 3차 결과 | X1: 최종상태 | Y1: 미팅메모 | Z1: 비고
A2: {=IF(B2:B987<>"", ROW(B2:B987)-1, "")} -> 1 | B2: 계약 완료 | D2: 해외구매대행 | E2: 정세희 | F2: 핫뜨 | G2: https://www.youtube.com/watch?v=elhxzHXqGRw | H2: O | I2: 개인 컨설팅 | J2: https://www.youtube.com/@hotdd2030/shorts | M2: 연락해봄 (기다림) | X2: 계약 완료
A3: 2 | B3: 계약 완료 | D3: 구글 온라인 자동화 수입 | E3: 김서윤 | F3: 선한부자 오가닉 | G3: https://class101.net/ko/products/61f68f1cf3a2e1000d780fda | H3: ㅇ | I3: 클래스 101 | J3: https://youtube.com/channel/UChIn7_WTuf2NcRBCvXgv2EA?si=HbthIS3jUHZtK_kV | K3: https://www.instagram.com/positiverich_organic?igsh=MXQwcmx4NDhmc2FhZQ== | M3: 연락해봄 (기다림) | R3: =IF(AND(S3=1,T3=0),"DM",IF(AND(S3=0,T3=1),"이메일",IF(AND(S3=1,T3=1),"DM+이메일",""))) | X3: 계약 완료
A4: 3 | B4: 계약 완료 | G4: https://weolbu.com/product?displaySeq=1002&utm_source=creator&utm_medium=affiliate&utm_campaign=class_organic&utm_content=traffic_creator_24&utm_term=youtube&fbclid=PAY2xjawHdzNVleHRuA2FlbQIxMAABppHOhAX0rOzfKK5kSFLSzIEFFXYHUBaYSTLJ-TOgoP6cQLcCGS8H_a_Igg_aem_-T_zv0UGunC1YUFbHudqEg | I4: 월부닷컴 | R4: =IF(AND(S4=1,T4=0),"DM",IF(AND(S4=0,T4=1),"이메일",IF(AND(S4=1,T4=1),"DM+이메일",""))) | X4: 계약 완료
A5: 4 | B5: 계약 완료 | D5: AI 상세페이지 | E5: 김상원 | F5: 디선제압 | G5: https://www.youtube.com/@%EB%94%94%EC%84%A0%EC%A0%9C%EC%95%95 | H5: X | M5: open.kakao.com/o/gWMf3K3g | R5: =IF(AND(S5=1,T5=0),"DM",IF(AND(S5=0,T5=1),"이메일",IF(AND(S5=1,T5=1),"DM+이메일",""))) | X5: 계약 완료
A6: 5 | B6: 계약 완료 | D6: 상세페이지 기획 (AI) | E6: 정승희 | F6: 페이지부스터 | G6: 유튜브 | H6: X | J6: 유튜브 | M6: 이메일 | R6: =IF(AND(S6=1,T6=0),"DM",IF(AND(S6=0,T6=1),"이메일",IF(AND(S6=1,T6=1),"DM+이메일",""))) | X6: 계약 완료
A7: 6 | B7: 계약 완료 | D7: AI 유튜브 수익화 | E7: 윤원경 | F7: 지인옥 (작가) | G7: 블로그 | H7: ? | I7: 런칭하려고 웨비나받음 | J7: http://www.youtube.com/@%EC%A7%80%EC%9D%B8%EC%98%A5 | K7: https://www.instagram.com/jee_writer?igsh=bHppbnV6dGwybm05 | L7: https://jeeinok.com/ai-youtube-landing | R7: =IF(AND(S7=1,T7=0),"DM",IF(AND(S7=0,T7=1),"이메일",IF(AND(S7=1,T7=1),"DM+이메일",""))) | X7: 계약 완료
A8: 7 | B8: 계약 완료 | D8: AI 숏츠 | E8: 국선우 | F8: 제이 온리 | G8: 인스타 | H8: o | I8: 개인 | K8: https://www.instagram.com/j_only8?utm_source=ig_web_button_share_sheet&igsh=cTJwMG9yZGpoMDh0 | R8: =IF(AND(S8=1,T8=0),"DM",IF(AND(S8=0,T8=1),"이메일",IF(AND(S8=1,T8=1),"DM+이메일",""))) | X8: 계약 완료
A9: 8 | B9: 계약 완료 | D9: AI 상세페이지 | E9: 정승희 | F9: 이지디자인 | G9: 유튜브 | H9: O | I9: 패스트 캠퍼스 | J9: https://www.youtube.com/@EasyDesign_ED/videos | K9: https://www.instagram.com/easy_design.ed/ | L9: easydesign502@gmail.com | M9: 누적 수강생 8,000명 | R9: =IF(AND(S9=1,T9=0),"DM",IF(AND(S9=0,T9=1),"이메일",IF(AND(S9=1,T9=1),"DM+이메일",""))) | X9: 계약 완료
A10: 9 | B10: 진행 중 | D10: 티스토리블로그, 구글애드센스 | E10: 김서윤 | F10: 리뷰요정리남 | G10: https://class101.net/ko/products/5dcd2c1f0bdefc4e498af73e | H10: O | I10: 클래스 101 | J10: https://www.youtube.com/channel/UCRx7_s9Mvw9j2mLSaj6X70g | K10: https://www.instagram.com/reviewyojung/# | L10: reviewyojung@naver.com | N10: =IF(AND(O10=1,P10=0),"DM",IF(AND(O10=0,P10=1),"이메일",IF(AND(O10=1,P10=1),"DM+이메일",""))) -> DM+이메일 | O10: 1 | P10: 1 | Q10: 0 | T10: 46108 | U10: 무응답 | V10: 2026.04.01
A11: 10 | B11: 진행 중 | D11: 생성형 AI | E11: 김지상 | F11: 챗GPT강사 이도혜 | H11: O | I11: 개인 | J11: https://www.youtube.com/@chatgpt.114/videos | K11: https://www.instagram.com/tiffany_story__ | L11: dohye.edu@gmail.com | M11: 너무 많은곳을하고있음 | N11: =IF(AND(O11=1,P11=0),"DM",IF(AND(O11=0,P11=1),"이메일",IF(AND(O11=1,P11=1),"DM+이메일",""))) -> DM+이메일 | O11: 1 | P11: 1 | Q11: 0 | T11: 46108 | U11: 무응답 | V11: 2026.04.01
A12: 11 | B12: 진행 중 | D12: 해외 및 국내 구매 대행 | E12: 정세희 | F12: 부추경자 | G12: 부추경자 블로그 https://www.youtube.com/watch?v=6xMbPBWr_AU | H12: O | I12: 현) 개인 컨설팅 전) 타이탄 수강생, 초청 강사 | J12: https://www.youtube.com/channel/UCsXCQkVgOZMwlaXqVr3rpjQ | K12: https://www.instagram.com/buchugj/ | L12: darmvit@naver.com | N12: =IF(AND(O12=1,P12=0),"DM",IF(AND(O12=0,P12=1),"이메일",IF(AND(O12=1,P12=1),"DM+이메일",""))) -> DM+이메일 | O12: 1 | P12: 1 | Q12: 0 | T12: 46108 | U12: 무응답 | V12: 2026.04.01
A13: 12 | B13: 진행 중 | D13: 소형 꼬마빌딩 수익화 | E13: 김지상 | F13: 차빌 TV | G13: 링크트리 | H13: X | J13: https://www.youtube.com/@TVchabuil | K13: https://www.instagram.com/chabuil_1/ | L13: chabuil@chabuil.com | N13: =IF(AND(O13=1,P13=0),"DM",IF(AND(O13=0,P13=1),"이메일",IF(AND(O13=1,P13=1),"DM+이메일",""))) -> DM+이메일 | O13: 1 | P13: 1 | Q13: 0 | T13: 46108 | U13: 무응답 | V13: 2026.04.01
A14: 13 | B14: 진행 중 | D14: 구매대행 | E14: 김지상 | F14: 사업하는 뚜벅이 | G14: 링크트리 | H14: O | I14: 비즈부스트 | J14: https://www.youtube.com/@Satddu | K14: https://www.instagram.com/satddu/ | L14: Innerpeaceer@gmail.com | N14: =IF(AND(O14=1,P14=0),"DM",IF(AND(O14=0,P14=1),"이메일",IF(AND(O14=1,P14=1),"DM+이메일",""))) -> DM+이메일 | O14: 1 | P14: 1 | Q14: 0 | T14: 46108 | U14: 무응답 | V14: 2026.04.01
A15: 14 | B15: 진행 중 | D15: 부동산 | E15: 김지상 | F15: 하니 | G15: 링크트리 | H15: O | I15: 클래스101 | J15: https://www.youtube.com/@WeelborgWilkens | K15: https://www.instagram.com/min_is__/ | N15: =IF(AND(O15=1,P15=0),"DM",IF(AND(O15=0,P15=1),"이메일",IF(AND(O15=1,P15=1),"DM+이메일",""))) -> DM | O15: 1 | P15: 0 | Q15: 0 | T15: 46108
A16: 15 | B16: 진행 중 | D16: (7월 2째주 시작) AI | E16: 이해수 | F16: AI돈나 | G16: https://www.youtube.com/@aidonnawa | H16: ? | J16: https://www.youtube.com/@aidonnawa | L16: bokhan2329@gmail.com | N16: =IF(AND(O16=1,P16=0),"DM",IF(AND(O16=0,P16=1),"이메일",IF(AND(O16=1,P16=1),"DM+이메일",""))) -> 이메일 | O16: 0 | P16: 1 | Q16: 0 | T16: 46108 | U16: 무응답 | V16: 2026.04.01
A17: 16 | B17: 진행 중 | D17: AI | E17: 김은진 | F17: gpt_kimsa | H17: ㅇ | I17: 개인강의/카카오 비즈니스 | J17: https://youtube.com/@gpt_kimisa?si=yMw3t-PGfBRjAGHJ | K17: https://www.instagram.com/gpt_kimisa?igsh=dXhidTVwdmFoc2d2 | L17: billykim1005@gmail.com | M17: 생성형 AI 강의 진행중 (자체 강의) | N17: =IF(AND(O17=1,P17=0),"DM",IF(AND(O17=0,P17=1),"이메일",IF(AND(O17=1,P17=1),"DM+이메일",""))) -> DM+이메일 | O17: 1 | P17: 1 | Q17: 0 | T17: 46108 | U17: 무응답 | V17: 2026.04.01
A18: 17 | B18: 진행 중 | D18: AI 상세페이지 | E18: 김예빈 | F18: 독립D | H18: x | J18: http://www.youtube.com/@doklip.D | K18: http://instagram.com/doklip.d | L18: doklip.d@gmail.com | N18: =IF(AND(O18=1,P18=0),"DM",IF(AND(O18=0,P18=1),"이메일",IF(AND(O18=1,P18=1),"DM+이메일",""))) -> DM+이메일 | O18: 1 | P18: 1 | Q18: 0 | T18: 46108 | U18: 무응답 | V18: 2026.04.01
A19: 18 | B19: 진행 중 | D19: AI 영상 | E19: 정세희 | F19: 왼손 WENSON AI | H19: o | I19: (소액)자체 강의 플랫폼 | J19: https://www.youtube.com/@wensonai/videos | L19: ilowme@naver.com | N19: =IF(AND(O19=1,P19=0),"DM",IF(AND(O19=0,P19=1),"이메일",IF(AND(O19=1,P19=1),"DM+이메일",""))) -> 이메일 | O19: 0 | P19: 1 | Q19: 0 | T19: 46108 | U19: 무응답 | V19: 2026.04.01
A20: 19 | B20: 진행 중 | D20: AI 로켓그로스 | E20: 정승희 | F20: 일렌 | G20: 유튜브 | H20: o | I20: 개인강의/10기 | J20: https://www.youtube.com/@ihlen_tv | K20: https://www.instagram.com/ihlen_online_business_coach/ | L20: ihlenco@naver.com | N20: =IF(AND(O20=1,P20=0),"DM",IF(AND(O20=0,P20=1),"이메일",IF(AND(O20=1,P20=1),"DM+이메일",""))) -> DM+이메일 | O20: 1 | P20: 1 | Q20: 0 | T20: 46108 | U20: 무응답 | V20: 2026.04.01
A21: 20 | B21: 진행 중 | D21: AI 영상 | E21: 정세희 | F21: 디스이즈머니 | G21: 전자책(블로그) | H21: x | J21: https://www.youtube.com/channel/UClP2hW295JL_o-lESiMY0fg/join | L21: boxtvstar@gmail.com | N21: =IF(AND(O21=1,P21=0),"DM",IF(AND(O21=0,P21=1),"이메일",IF(AND(O21=1,P21=1),"DM+이메일",""))) -> 이메일 | O21: 0 | P21: 1 | Q21: 0 | T21: 46108 | U21: 무응답 | V21: 2026.04.01
A22: 21 | B22: 진행 중 | D22: AI 영상 | E22: 정세희 | F22: 사이드퀘스트 | H22: X | J22: https://www.youtube.com/@%EC%82%AC%EC%9D%B4%EB%93%9C%ED%80%98%EC%8A%A4%ED%8A%B8/videos | L22: SideQuest316@gmail.com | N22: =IF(AND(O22=1,P22=0),"DM",IF(AND(O22=0,P22=1),"이메일",IF(AND(O22=1,P22=1),"DM+이메일",""))) -> 이메일 | O22: 0 | P22: 1 | Q22: 0 | T22: 46108 | U22: 무응답 | V22: 2026.04.01
A23: 22 | B23: 진행 중 | D23: 부동산 경매 | E23: 윤예영 | F23: 알론소운(고운정) | G23: 패스트캠퍼스 | H23: O | I23: 패스트캠퍼스 | J23: https://www.youtube.com/@alonso_woon | L23: alonso_woon@naver.com | M23: VOD판매중 | N23: =IF(AND(O23=1,P23=0),"DM",IF(AND(O23=0,P23=1),"이메일",IF(AND(O23=1,P23=1),"DM+이메일",""))) -> 이메일 | O23: 0 | P23: 1 | Q23: 0 | T23: 46108 | U23: 무응답 | V23: 2026.04.01
A24: 23 | B24: 진행 중 | D24: AI스마트스토어 | E24: 윤예영 | F24: 한이룸 | G24: 패스트캠퍼스 | H24: O | I24: 패스트캠퍼스 | J24: https://www.youtube.com/@irum_hahn/videos | L24: cole@rebrandb.com | M24: VOD판매중 | N24: =IF(AND(O24=1,P24=0),"DM",IF(AND(O24=0,P24=1),"이메일",IF(AND(O24=1,P24=1),"DM+이메일",""))) -> 이메일 | O24: 0 | P24: 1 | Q24: 0 | T24: 46108 | U24: 무응답 | V24: 2026.04.01
A25: 24 | B25: 진행 중 | D25: AI 유튜브 쇼츠 | E25: 김승철 | F25: 돈강TV | G25: 강의 페이지 | H25: X | I25: Kmong | J25: https://www.youtube.com/@%EB%8F%88%EA%B0%95/featured | L25: donkang97@naver.com | M25: VOD 판매 중 | N25: =IF(AND(O25=1,P25=0),"DM",IF(AND(O25=0,P25=1),"이메일",IF(AND(O25=1,P25=1),"DM+이메일",""))) -> 이메일 | O25: 0 | P25: 1 | Q25: 0 | T25: 46108 | U25: 무응답 | V25: 2026.04.01
A26: 25 | B26: 진행 중 | D26: AI전자책 | E26: 윤예영 | F26: 함프로 | G26: 탈잉 | H26: O | I26: 탈잉 | K26: https://www.instagram.com/ebook_hampro/?hl=ko | M26: VOD판매중,와디즈 펀딩 이력 | N26: =IF(AND(O26=1,P26=0),"DM",IF(AND(O26=0,P26=1),"이메일",IF(AND(O26=1,P26=1),"DM+이메일",""))) -> DM | O26: 1 | P26: 0 | Q26: 0 | T26: 46108
A27: 26 | B27: 진행 중 | D27: AI 수익화(GPT) | E27: 김지상 | F27: 갓진주(송진주) | G27: 블로그 | H27: O | I27: 자체 강의 | J27: https://www.youtube.com/@%EA%B0%93%EC%A7%84%EC%A3%BC | K27: https://www.instagram.com/gotjinju/ | N27: =IF(AND(O27=1,P27=0),"DM",IF(AND(O27=0,P27=1),"이메일",IF(AND(O27=1,P27=1),"DM+이메일",""))) -> DM | O27: 1 | P27: 0 | Q27: 0 | T27: 46108
A28: 27 | B28: 진행 중 | D28: AI 광고이미지 제작 | E28: 정승희 | F28: 반토막AI | G28: 유튜브 | H28: O | I28: 자체 카페 | J28: https://www.youtube.com/@%EB%B0%98%ED%86%A0%EB%A7%89AI | K28: https://www.instagram.com/halfcut_ai/ | L28: wpgursla1@gmail.com | N28: =IF(AND(O28=1,P28=0),"DM",IF(AND(O28=0,P28=1),"이메일",IF(AND(O28=1,P28=1),"DM+이메일",""))) -> DM+이메일 | O28: 1 | P28: 1 | Q28: 0 | T28: 46108 | U28: 무응답 | V28: 2026.04.01
A29: 28 | B29: 진행 중 | D29: AI시니어 | E29: 이해수 | F29: 채널-지혜우물 | G29: 유튜브 | H29: ? | J29: https://www.youtube.com/@%EC%A7%80%ED%98%9C%EC%9A%B0%EB%AC%BC | L29: hustledaram@gmail.com | N29: =IF(AND(O29=1,P29=0),"DM",IF(AND(O29=0,P29=1),"이메일",IF(AND(O29=1,P29=1),"DM+이메일",""))) -> 이메일 | O29: 0 | P29: 1 | Q29: 0 | T29: 46108 | U29: 무응답 | V29: 2026.04.01
A30: 29 | B30: 진행 중 | D30: AI 시니어 외 다수 | E30: 이해수 | F30: 이재인/ 이니언니 | G30: 유튜브 | H30: O | I30: 개인 | J30: https://www.youtube.com/@ini_unnie | K30: https://www.instagram.com/ini_unnie/ | L30: AICMKorea@gmail.com | M30: 리틀리/ | N30: =IF(AND(O30=1,P30=0),"DM",IF(AND(O30=0,P30=1),"이메일",IF(AND(O30=1,P30=1),"DM+이메일",""))) -> DM+이메일 | O30: 1 | P30: 1 | Q30: 0 | T30: 46108 | U30: 무응답 | V30: 2026.04.01
A31: 30 | B31: 진행 중 | D31: AI 영상 | E31: 정세희 | F31: 야옹멍 YaongMeong | G31: 틱톡 | H31: X | J31: https://www.youtube.com/@%EC%95%BC%EC%98%B9%EB%A9%8DYaongMeong | L31: mgmsdiary@gmail.com | N31: =IF(AND(O31=1,P31=0),"DM",IF(AND(O31=0,P31=1),"이메일",IF(AND(O31=1,P31=1),"DM+이메일",""))) -> 이메일 | O31: 0 | P31: 1 | Q31: 0 | T31: 46108 | U31: 무응답 | V31: 2026.04.01
A32: 31 | B32: 진행 중 | D32: AI 쇼츠 | E32: 김은진 | F32: 슈퍼봇 | G32: 유튜브 | H32: O | I32: 클래스101 | J32: https://www.youtube.com/@_Superbot_ | K32: https://www.instagram.com/superbot_origin/?igsh=OGQ5ZDc2ODk2ZA%3D%3D&utm_source=qr# | L32: jumptipsy@gmail.com | M32: 요즘 것들 돈버는 이야기,일터뷰 츨연 | N32: =IF(AND(O32=1,P32=0),"DM",IF(AND(O32=0,P32=1),"이메일",IF(AND(O32=1,P32=1),"DM+이메일",""))) -> DM+이메일 | O32: 1 | P32: 1 | Q32: 0 | T32: 46108 | U32: 응답 | Y32: 연락 대기중
A33: 32 | B33: 진행 중 | D33: AI 스레드 | E33: 김상원 | F33: 원모어띵 | G33: 인터뷰 출연 | H33: O | I33: 자체플랫폼 | J33: https://www.youtube.com/@growthyoungduk | L33: onemorething9196@gmail.com | N33: =IF(AND(O33=1,P33=0),"DM",IF(AND(O33=0,P33=1),"이메일",IF(AND(O33=1,P33=1),"DM+이메일",""))) -> 이메일 | O33: 0 | P33: 1 | Q33: 0 | T33: 46108 | U33: 무응답 | V33: 2026.04.01
A34: 33 | B34: 진행 중 | D34: AI 유튜브 | E34: 장찬민 | F34: AI ON 에이아이온 | G34: 유튜브 | H34: X | J34: https://www.youtube.com/@AION%EB%8F%88%EB%B2%84%EB%8A%94%EB%B2%95 | L34: aion.official.ai@gmail.com | M34: 운영하는 블로그, aion.official.ai@gmail.com | N34: =IF(AND(O34=1,P34=0),"DM",IF(AND(O34=0,P34=1),"이메일",IF(AND(O34=1,P34=1),"DM+이메일",""))) -> 이메일 | O34: 0 | P34: 1 | Q34: 0 | T34: 46108 | U34: 무응답 | V34: 2026.04.01
A35: 34 | B35: 진행 중 | D35: AI 콘텐츠 | E35: 원소영 | F35: 유투브 하는 남자 디노 | G35: 유투브 | H35: X | J35: https://www.youtube.com/channel/UC3iyduO41XsWKZsYkE5FNyQ/join | L35: worksong87@gmail.com | M35: 네이버카페 | N35: =IF(AND(O35=1,P35=0),"DM",IF(AND(O35=0,P35=1),"이메일",IF(AND(O35=1,P35=1),"DM+이메일",""))) -> 이메일 | O35: 0 | P35: 1 | Q35: 0 | T35: 46108 | U35: 무응답 | V35: 2026.04.01
A36: 35 | B36: 진행 중 | D36: AI, GPT 전문가 | E36: 장찬민 | F36: 알린 | G36: 유튜브 | H36: O | I36: 자체 플랫폼 | J36: https://www.youtube.com/@ailifeinnovation | K36: http://instagram.com/ailifeinnovation | L36: ailifeinnovation@gmail.com | M36: ailifeinnovation@gmail.com | N36: =IF(AND(O36=1,P36=0),"DM",IF(AND(O36=0,P36=1),"이메일",IF(AND(O36=1,P36=1),"DM+이메일",""))) -> DM+이메일 | O36: 1 | P36: 1 | Q36: 0 | T36: 46108 | U36: 무응답 | V36: 2026.04.01
A37: 36 | B37: 진행 중 | D37: AI 콘텐츠 | E37: 원소영 | F37: Creator Profit Lab | G37: 유투브 | H37: X | J37: https://www.youtube.com/@CreatorProfitLabKR/shorts | K37: http://instagram.com/adaisy.click24 | M37: AI를 이용한 인스타툰, 블로그 글, 유투브 등 제작 | N37: =IF(AND(O37=1,P37=0),"DM",IF(AND(O37=0,P37=1),"이메일",IF(AND(O37=1,P37=1),"DM+이메일",""))) -> DM | O37: 1 | P37: 0 | Q37: 0 | T37: 46108
A38: 37 | B38: 진행 중 | D38: 전자책 | E38: 이해수 | F38: 원더로이 | G38: 카페 | H38: o | I38: 월부 | K38: https://www.instagram.com/wonder_roy_world/ | L38: wonder_roy@naver.com | N38: =IF(AND(O38=1,P38=0),"DM",IF(AND(O38=0,P38=1),"이메일",IF(AND(O38=1,P38=1),"DM+이메일",""))) -> DM+이메일 | O38: 1 | P38: 1 | Q38: 0 | T38: 46108 | U38: 무응답 | V38: 2026.04.01
A39: 38 | B39: 진행 중 | D39: 유튜브, 디자인 부수입 | E39: 정승희 | F39: 돈디 | G39: 블로그 | J39: https://www.youtube.com/@%EB%8F%88%EB%94%94AI | K39: https://www.instagram.com/dondi_ai_/ | L39: artist8012@naver.com | N39: =IF(AND(O39=1,P39=0),"DM",IF(AND(O39=0,P39=1),"이메일",IF(AND(O39=1,P39=1),"DM+이메일",""))) -> DM+이메일 | O39: 1 | P39: 1 | Q39: 0 | T39: 46108 | U39: 무응답 | V39: 2026.04.01
A40: 39 | B40: 진행 중 | D40: AI, GPT 전문가 | E40: 김지상 | F40: AI 멘토 천꿈이 | G40: 인스타 | H40: o | I40: 개인 | K40: https://www.instagram.com/slow_life_kr/ | L40: limonsparkk@gmail.com | N40: =IF(AND(O40=1,P40=0),"DM",IF(AND(O40=0,P40=1),"이메일",IF(AND(O40=1,P40=1),"DM+이메일",""))) -> DM+이메일 | O40: 1 | P40: 1 | Q40: 0 | T40: 46108 | U40: 무응답 | V40: 2026.04.01
...

Sheet 미팅 예정
A1: No. | B1: 담당자 | C1: 강사명 | D1: 분야 | E1: 미팅 일정 | F1: SNS | G1: 상태 | H1: 강사 정보 | I1: 특이사항
A2: 1 | B2: 정승희 | C2: 리셀이코치 | D2: 리셀, 아마존 | E2: 4/1(수) 17:00 | F2: 유튜브 | G2: 진행 중 | H2: 리셀로 연매출 10억 (아마존 추정)
A3: 2 | B3: 정승희 | C3: 김나무 | D3: 이모티콘 작가 데뷔 | E3: 4/2(목) 11:00 | F3: 인스타 | G3: 진행 중 | H3: 탈잉에서 활동 중
A4: 3 | B4: 정승희 | C4: 팅쌤 | D4: 한국어, 에어비앤비 | E4: 4/2(목) 13:00 | F4: 유튜브 | G4: 진행 중 | H4: 한국어 강사, 월 매출 1,500 | I4: 웰클래스 소속, 미팅 취소 될 수 있음
A5: 4 | B5: 정승희 | C5: 세지쌤_임영순 | D5: 쇼핑 숏폼 | E5: 4/2(목) 15:00 (줌) | F5: 카카오톡 | G5: 진행 중 | H5: 세지스쿨 - 코치, 쇼핑 숏폼 강사
A6: 5 | B6: 정승희 | C6: 딱쉬운경공매 | D6: 소액 경매 | E6: 4/6(월) 15:00 (줌) | F6: 유튜브 | G6: 진행 중 | H6: 소액 경매, 공매 - 자체 강의 진행 중
A7: 23 | B7: 정승희 | C7: 김은량 | D7: 시니어 준비생 | E7: 4/6(월) 14:00 | F7: 010-6864-6800 | G7: 진행 중 | H7: 월 300정도, 멤버십, 클래스 101, 광고업체 협업(이번달 1회,300만) | I7: 본부장님은 미팅 참여x
A8: 6 | B8: 정승희 | C8: 도루묵(김윤주) | D8: N잡•그림•디자인수익화•재테크 | F8: 인스타 | G8: 진행 중 | H8: 인스타 팔로우 1만, 수익은 얼마 없는 듯 | I8: 미팅 일정 및 방법 조율 중
A9: 7 | B9: 정승희 | C9: 쏘하 | D9: 릴스 제작 | F9: 인스타 | G9: 진행 중 | I9: 인스타로 긍정반응 - 아직 개별 연락 X
A10: 8 | B10: 정승희 | C10: 슈퍼봇 | D10: AI 강의 | F10: 인스타 | G10: 진행 중 | H10: 클래스 101 AI 1등 강사 | I10: 인스타로 긍정반응 - 아직 개별 연락 X
A11: 9 | B11: 정승희 | C11: 김명선 | D11: 건강 쇼츠 | F11: 블로그 | G11: 보류 | I11: 현재 바빠서 연락 어려움 (4월 둘 째주쯤 연락 ㄱ)
A12: 10 | B12: 정승희 | C12: 김지안 | D12: 성과우수_온백 1기 | F12: 010-3374-5569 | G12: 진행 중 | I12: 문자 소통 중
A13: 11 | B13: 정승희 | C13: 박현주 | D13: 성과우수_셀팜 5기 농수산물 | F13: 010-9082-2766 | G13: 제외 | I13: 문자 소통 중
A14: 12 | B14: 정승희 | C14: 강종현 | D14: 성과우수_셀팜 3기 유투브 | F14: 010-7556-4797 | G14: 진행 중 | I14: 문자 소통 중
A15: 13 | B15: 정승희 | C15: 김민 | D15: 성과우수_셀팜 3기 농수산물 | F15: 010-8255-9215 | G15: 제외 | I15: 부담 느껴 거절
A16: 14 | B16: 정승희 | C16: 정재호 | D16: 부자꿈틀 1기 | F16: 010-4113-2579 | G16: 진행 중 | I16: 문자 소통 중
A17: 15 | B17: 정승희 | C17: 김지은 | D17: 민대표 1기 | F17: 010-5894-4111 | G17: 진행 중 | I17: 문자 소통 중
A18: 16 | B18: 정승희 | C18: 박수경 | D18: 부자꿈틀 2기 | F18: 010-2953-4913 | G18: 진행 중 | I18: 문자 소통 중
A19: 17 | B19: 정승희 | C19: 정경진 | D19: 부자꿈틀 2기 | F19: 010-8231-2575 | G19: 제외 | I19: 부담 느껴 거절
A20: 18 | B20: 정승희 | C20: 이효군 | D20: 부자꿈틀 1기 | F20: 010-9080-5838 | G20: 진행 중 | I20: 문자 소통 중
A21: 19 | B21: 정승희 | C21: 김소완 | D21: 부자꿈틀 1기 | F21: 010-4813-3868 | G21: 제외 | I21: 문자 소통 중
A22: 20 | B22: 정승희 | C22: 오설미 (회신체크) | D22: 부자꿈틀 시니어 2기 | F22: 010-2400-5453 | G22: 진행 중 | I22: 문자 소통 중
A23: 21 | B23: 정승희 | C23: 문아영 | D23: 부자꿈틀 3기 | F23: 010-6653-5103 | G23: 제외 | I23: 전화 완료, 강사 매력도 떨어져서 여기서 마무리
A24: 22 | B24: 정승희 | C24: 오용훈 | D24: 플레이리스트 채널 운영 중 | E24: 5월 예정 | F24: 유튜브, 010-5579-7971 | G24: 진행 중 | I24: 강사 관심 높음, 검증은 안 됨, 5월 달에 미팅 예정
A25: 24
A26: 25
A27: 26
A28: 27
A29: 28
A30: 29
A31: 30
A32: 31
A33: 32
A34: 33
A35: 34
A36: 35
... A49: 48

Sheet Claude Cache
A1: ⚠️ SHEET RESERVED FOR =CLAUDE... FUNCTIONS. DO NOT EDIT! ⚠️
A2: Key | B2: Value | C2: Expiration

Sheet 1차메시지
C1: DM (발송 예정) | I1: 이메일 (발송 예정)
C4: 안녕하세요, [강사명]님. (주) 핏크닉 대표 정승요입니다. :) 우연찮게 대표님의 [콘텐츠]를 인상 깊게 보고 연락을 드렸습니다. (이런 연락을 자주 드리진 않습니다.. ㅎㅎ) 저희 핏크닉은 온, 오프라인 강의 플랫폼입니다. 현재 핏크닉에는 41명 이상의 전문가께서 강사로 활약하며, 수강생들의 성과를 돕고 있습니다. 핏크닉이 추구하는 1순위 가치는 '성장'입니다. 이 성장을 숫자로 표현하면 다음과 같습니다. - 평균 강사 기수 : 4기수↑ - 강의 만족도 : 8.6/10점 - 강의 추천 의향 : 84.7% (설문 참여 인원 : 1,084명) 이처럼 핏크닉은 강사, 수강생 모두에게 실질적인 성장을 만들어드리고 있습니다. 대표님께서 핏크닉과 함께하신다면, 가지신 노하우와 가치를 더 많은 사람들에게 전달할 수 있을 뿐만 아니라, 그 과정에서 강사님의 브랜드와 전문성이 자연스럽게 쌓이는 경험을 제공해드릴 수 있습니다. 관련하여 가볍게 커피챗하면서 이야기를 나눠보시면 어떠실까요? :) 물론 부담을 가지실 필요는 전혀 없습니다. 미팅이 아닌 서로의 인사이트를 나누는 자리라고 생각하시면 좋을 것 같습니다. ^^ 제가 미팅이 많아 본부장님 연락처를 첨부드리며, 연락주시면 스케줄 조율하여 미팅 잡아주실 것입니다. 편하게 연락주시면 됩니다 :) 앞으로 좋은 인연이 되길 바라겠습니다. 감사합니다. (주) 핏크닉 대표 정승요 드림 본부장 연락처 : 010-7631-9761 홈페이지 : fitchnic.com | I4: 제목 : [강사명]님께 드리는 제안 안녕하세요, [강사명]님. (주) 핏크닉 대표 정승요입니다. :) 우연찮게 대표님의 [콘텐츠]를 인상 깊게 보고 꼭 한번 이야기를 나눠보고 싶어 메일을 드렸습니다. 원래 이런 연락을 자주 드리지 않습니다만, [강사명]님이 가진 노하우와 콘텐츠를 보면서 대표님과 함께 정말 의미 있는 협업을 할 수 있겠다는 생각이 들어 연락을 드렸습니다. 핏크닉이 어떤 곳인지 먼저 말씀드릴게요. 저희 핏크닉은 온, 오프라인 강의 플랫폼으로 41명 분이 강사님과 함께하고 있습니다. 핏크닉이 추구하는 가장 중요한 가치는 '성장'입니다. 이 성장을 숫자로 표현하면 다음과 같습니다. - 평균 강사 기수 : 4기수↑ - 강의 만족도 : 8.6 / 10점 - 강의 추천 의향 : 84.7% (설문 참여 인원 : 1,084명) 숫자가 전부를 말해주진 않지만, 핏크닉이 강사님과 수강생의 성장을 얼마나 중요하게 생각하는지는 확인할 수 있다고 생각합니다. [강사명]님께서 핏크닉과 함께하신다면, 가지신 노하우와 가치를 더 많은 사람들에게 전달할 수 있을 뿐만 아니라, 그 과정에서 강사님의 브랜드와 전문성이 자연스럽게 쌓이는 경험을 제공해드릴 수 있습니다. 관련하여 가볍게 커피챗하면서 이야기를 나눠보시면 어떠실까요? :) 물론 부담을 가지실 필요는 전혀 없습니다. 미팅이 아닌 서로의 인사이트를 나누는 자리라고 생각하시면 좋을 것 같습니다. ^^ 제가 미팅이 많아 본부장님 연락처를 첨부드리며, 연락주시면 스케줄 조율하여 미팅 잡아주실 것입니다. 편하게 연락주시면 됩니다 :) 앞으로 좋은 인연이 되길 바라겠습니다. 감사합니다. ^^ (주) 핏크닉 대표 정승요 드림 본부장 연락처 : 010-7631-9761 홈페이지 : fitchnic.com

Sheet 2차메시지
C1: 이메일 | J1: 2차 변형 - DM + 이메일 (진행 중)
C4: 제목 : [강사명]님, 주식회사 핏크닉 대표 정승요입니다. :) 안녕하세요, [강사명]님. (주) 핏크닉 대표 정승요입니다. :) 지난번 메일에서 핏크닉 소개가 조금 부족했던 것 같아 이렇게 다시 한번 연락드립니다. 강의 연락을 받으셨을 때, 아마 이런 생각을 하셨을 것 같습니다. '내가 강의를 잘 만들 수 있을까?' '기획이나 마케팅을 해준다고 하는데, 실제로 얼마나 해줄까?' '혼자 해도 되는데 굳이 같이 해야 할 이유가 있을까?' 제가 현역 강사이니, 강사님들의 고충을 누구보다 잘 알고 있다고 생각하는데요. ㅎㅎ 개인이 강의를 기획부터 운영을 하게 되면 생기는 문제는 간단합니다. 바로 '강의 자체에 집중하기가 어렵다는 것'입니다. 수강생 모집, CS, 과제 관리, 기수 관리까지 강의 하나에 들어가는 일이 생각보다 많습니다. 수강생 모집 단계에서 막히는 경우도 대부분이고요. 결국 강사님께서 돈, 시간만 낭비하는 경우를 정말 많이 봐왔습니다. 핏크닉 강사님들께서 핏크닉과 오래 함께하시는 이유가 바로 여기에 있습니다. 저희는 강의 기획부터 마케팅, 촬영, 운영까지 전 과정을 함께해드리고 있습니다. 담당 PM, PD, CS팀이 배정되어 강사님께서 오롯이 강의에만 몰입하실 수 있는 환경을 만들어드립니다. 또한 정산 과정도 그 어떤 곳보다 투명하게 진행하고 있습니다. 그리고 또 하나 자부할 수 있는 건, 누구보다 대표가 열심히 한다는 점입니다. ㅎㅎ 제가 강사님들과 직접 부딪히며 일하기 때문에, 강사님들이 어떤 부분이 가장 힘들고 어떤 부분에서 막히는지 잘 압니다. 수강생 모집이 안 될 때, 커리큘럼을 어떻게 짜야 할지 막막할 때, 수강생 CS가 쌓여서 강의에 집중이 안 될 때. 그 답답함이 어떤 건지 알기 때문에 대표인 제가 직접 발로 뛰면서 케어해드리고 있습니다. 문제가 생겼을 때 가장 빠르게 움직일 수 있는 사람이 저라고 생각하거든요. [강사명]님! 2026년 핏크닉과 함께 압도적인 성장을 해보시죠. :) 핏크닉에서 책임지고 강사님의 성장을 돕겠습니다. 부담 가지실 것 없습니다. 가볍게 커피 한 잔 하신다고 생각하시면 좋을 것 같습니다. :) 제가 미팅이 많아 본부장님 연락처를 첨부드리며, 연락주시면 스케줄 조율하여 미팅 잡아주실 것입니다. 편하게 연락주시면 됩니다 :) 좋은 인연이 되길 기대하겠습니다. 감사합니다. ^^ (주) 핏크닉 대표 정승요 드림 본부장 연락처 : 010-7631-9761 홈페이지 : fitchnic.com | J4: 안녕하세요, 대표님. 지난번에 연락드렸던 (주) 핏크닉 대표 정승요입니다. 꽤 오랜만에 다시 연락드리네요. ㅎㅎ 그동안 잘 지내셨는지요. 그동안 타이밍이 맞지 않아 아쉬웠는데, 이번에 대표님의 콘텐츠를 보면서 다시 한번 연락드리고 싶었습니다. :) 그동안 핏크닉도 많은 성장을 해왔습니다. 그 성장을 숫자로 표현하자면 다음과 같습니다. - 핏크닉 강사 평균 강의 기수 : 4기수↑ - 평균 강의 만족도 : 8.6 / 10점 - 평균 강의 추천 의향 : 84.7% (설문 참여 인원 : 1,084명) 숫자가 전부를 말해주진 않지만, 핏크닉이 강사님과 수강생의 성장을 얼마나 중요하게 생각하는지는 확인할 수 있다고 생각합니다. 대표님께서 핏크닉과 함께하신다면, 가지신 노하우와 가치를 더 많은 사람들에게 전달할 수 있을 뿐만 아니라, 그 과정에서 강사님의 브랜드와 전문성이 자연스럽게 쌓이는 경험을 제공해드릴 수 있습니다. 짧지 않은 기간동안 핏크닉은 많은 성장을 하였습니다. 그리고 대표님의 성장을 책임질 수 있는 환경을 갖추었다고 자신합니다. 관련하여 가볍게 커피챗하면서 이야기를 나눠보시면 어떠실까요? :) 혹시라도 이전과 상황과 생각이 바뀌셨다면, 부담 없이 서로의 이야기를 나눠도 좋을 것 같습니다. 제가 미팅이 많아 본부장님 연락처를 첨부드리며, 연락주시면 스케줄 조율하여 미팅 잡아주실 것입니다. 편하게 연락주시면 됩니다 :) 앞으로 좋은 인연이 되길 바라겠습니다. 감사합니다. ^^ (주) 핏크닉 대표 정승요 드림 본부장 연락처 : 010-7631-9761 홈페이지 : fitchnic.com

Sheet 3차메시지
D1: 이메일
D4: 제목 : 대표님, 마지막으로 인사드립니다. :) 안녕하세요, 대표님. (주) 핏크닉 대표 정승요입니다. :) 두 번 정도 메일을 드렸는데, 이번이 마지막 메일입니다. 바쁘셔서 못 보셨을 수도 있고, 지금 당장 관심이 없으실 수도 있습니다. 어떤 이유든 충분히 이해합니다. 다만 한 가지만 말씀드리고 싶습니다. 강의는 타이밍이 중요합니다. 시장이 원할 때 시작하는 강의와 그 타이밍을 놓친 강의는 결과가 달라지거든요. 나중에 마음이 생기셨을 때, 핏크닉과 대표님이 함께할 수 있으면 좋겠습니다. 언제든 편하게 연락 주세요. 문은 항상 열려 있습니다. :) 대표님의 성장과 성공을 늘 응원하겠습니다. 감사합니다. ^^ (주) 핏크닉 대표 정승요 드림 본부장 연락처 : 010-7631-9761 홈페이지 : fitchnic.com

Sheet SMS단체메일
B3: SMS | H3: 단체발송 메일 (개인화x)
B5: 안녕하세요, 대표님 :) 핏크닉 김상원 본부장입니다. 오랜만에 연락드립니다. ^^ 연락을 드린 이유는 대표님께 핏크닉 강사를 제안드리고 싶어서입니다. 대표님이 내신 성과를 보니, 강사로서 충분히 좋은 모습을 보여주실 수 있으실 것 같아서요. :) 아쉬운 마음에 한번 더 연락을 드립니다. (아무에게나 이런 연락을 드리지 않습니다. ㅎㅎ) 아마 갑자기 이런 말씀을 드리면 '내가 강사를 할 수 있을까?' 겁부터 나실 것 같은데요. ^^.. 하지만 걱정하실 필요는 것이 현재 핏크닉에서 가장 후기가 좋은 강사분은 '핏크닉 수강생' 출신이십니다. :) 대표님과 똑같은 상황에서 출발하셨지만 지금은 스타 강사가 되어 수많은 분들의 수익화를 돕고 계십니다. 또한 좋은 강의를 만들기 위해 담당 PM이 함께하여 강의 커리큘럼부터, CS 등 담당 전문가가 함께 도와드실 예정입니다. 강사분들이 몰입할 수 있는 환경을 제공해드리니 너무 걱정하지 않으셨으면 합니다. :) 협업 관련하여 핏크닉에서 가볍게 미팅 한 번 해보시는 건 어떠실까요? 꼭 강사가 아니더라도 함께 커피 한 잔 하시면서 인사이트 나눌 수 있는 시간을 가지면 좋을 것 같습니다. :) 사무실로 직접 방문이 어려우시다면, 줌(Zoom)으로도 가능합니다. 괜찮으신 시간이나 날짜 말씀해주시면 일정 잡아보겠습니다. 편하게 답장 부탁드리겠습니다. 감사합니다. ^^ | H5: 안녕하세요, (주) 핏크닉 대표 정승요입니다. :) 우연찮게 대표님의 [채널 콘텐츠]를 인상 깊게 보고 꼭 한번 이야기를 나눠보고 싶어 메일을 드렸습니다. 원래 이런 연락을 자주 드리지 않습니다만, 채널의 퀄리티와 가능성을 보며 함께 정말 의미 있는 협업을 할 수 있겠다는 생각이 들어 연락을 드렸습니다. 핏크닉이 어떤 곳인지 먼저 말씀드릴게요. 저희 핏크닉은 온, 오프라인 강의 플랫폼으로 41명의 강사님과 함께하고 있습니다. 핏크닉이 추구하는 가장 중요한 가치는 '성장'입니다. 이 성장을 숫자로 표현하면 다음과 같습니다. - 평균 강사 기수 : 4기수↑ - 강의 만족도 : 8.6 / 10점 - 강의 추천 의향 : 84.7% (설문 참여 인원 : 1,084명) 숫자가 전부를 말해주진 않지만, 핏크닉이 강사님과 수강생의 성장을 얼마나 중요하게 생각하는지는 확인할 수 있다고 생각합니다. 대표님께서 핏크닉과 함께하신다면, 가지신 노하우와 가치를 더 많은 사람들에게 전달할 수 있을 뿐만 아니라, 그 과정에서 강사님의 브랜드와 전문성이 자연스럽게 쌓이는 경험을 제공해드릴 수 있습니다. 관련하여 가볍게 커피챗하면서 이야기를 나눠보시면 어떠실까요? :) 물론 부담을 가지실 필요는 전혀 없습니다. 미팅이 아닌 서로의 인사이트를 나누는 자리라고 생각하시면 좋을 것 같습니다. ^^ 제가 미팅이 많아 본부장님 연락처를 첨부드리며, 연락주시면 스케줄 조율하여 미팅 잡아주실 것입니다. 편하게 연락주시면 됩니다 :) 앞으로 좋은 인연이 되길 바라겠습니다. 감사합니다. ^^ (주) 핏크닉 대표 정승요 드림 본부장 연락처 : 010-7631-9761 홈페이지 : fitchnic.com
M7: [채널 콘텐츠] 부분은 수정 필요!
M8: -> 예. 플레이리스트 콘텐츠, 시니어 콘텐츠 등

Sheet 연락금지
A1: 🚫 연락금지 목록
A2: A열에 강사명(활동명) 입력 → markBanned() 실행 → 강사모집 탭 해당 행 빨간색 자동 표시
A4: 연락금지 플랫폼 (추가 가능)
A5: 타이탄클래스
A6: 인베이더스쿨
A7: 코주부클래스
A8: N잡연구소
A9: 사이클해커스
A17: 강사명 (활동명) | B17: 소속 플랫폼 | C17: 사유 | E17: 인스타그램 ID | F17: 닉네임
A18: 머니몬스터 | B18: 인베이더스쿨 | C18: 현역 강사 | E18: ssong_toon | F18: 뻥안치고
A19: 신영선 | B19: 타이탄클래스 | C19: 현역 강사 | E19: ism_maker | F19: 황원택
A20: 저스트고 | B20: 타이탄/인베이더스쿨 | C20: 현역 강사 | E20: loat_gang | F20: 갱
A21: 방구석 농부 | B21: 코주부클래스 | C21: 현역 강사 | E21: nan_on_u | F21: 이온유
A22: 유캐빈 | B22: 사이클해커스 | C22: 현역 강사 | E22: frenchluxury_ceo | F22: 프렌치럭셔리 [35년 장인 이불/럭셔리 리빙]
A23: 빈이파파 | B23: 코주부클래스 | C23: 현역 강사 | E23: titantools__ | F23: 오윤록 l 타철
A24: 엘제이 | B24: 사이클해커스 | C24: 현역 강사 | E24: wns_rl2002 | F24: 민준기
A25: 나리테일 | B25: 코주부클래스 | C25: 현역 강사 | E25: az__eden | F25: 유찬종
A26: 이도전 | B26: 타이탄클래스 | C26: 현역 강사 | E26: hslimlaw | F26: 임현서 변호사
A27: 양요다 | B27: 사이클해커스 | C27: 현역 강사 | E27: jokyum.kim | F27: 김조겸 세무사
A28: 혜다 | B28: 사이클해커스 | C28: 현역 강사 | E28: studiohive.official | F28: 당일보정 바디프로필ㅣ스튜디오 하이브
... A32: 최영호 | B32: 사이클해커스 | C32: 현역 강사 | E32: _doji_o_o | F32: 이도인
A33: 저스트고 | B33: 인베이더스쿨 | E33: kj_93 | F33: 권기동
A34: 메리 | B34: 타이탄클래스 | E34: roomfinder.kr | F34: 숙소찾아주는남자
A35: 션 | B35: N잡연구소 | E35: mountain.chicken | F35: 마운틴치킨
A36: 보거스 | B36: 인베이더스쿨 | E36: alphamale__2025 | F36: 애드센스 전문가 | 알파남 김지수
A37: 콘파남 | B37: 사이클해커스 | E37: rubypapa_travel | F37: 루비파파 | 가족 여행 육아 크리에이터
A38: 긍정필터 | B38: 아이비클래스 | E38: _happy_elin | F38: 병원마케팅 기준 | 엘린
A39: 주건 | B39: 타이탄클래스 | E39: flourprince | F39: 신민규
A40: 부자매 | B40: 돈클 | E40: gyeongju.si | F40: 경주특별시
A41: 연화선녀 | B41: 코주부클래스 | E41: firelab_pi | F41: 파이
A42: 준호 | B42: 타이탄클래스 | E42: gowva1 | F42: 김지호
A43: 지구미 | B43: N잡연구소 | E43: worldvisionkorea | F43: 월드비전 공식 인스타그램
A44: 운대표 | B44: N잡연구소 | E44: cowboy_grill | F44: 카우보이그릴
... A73: 조은정 | B73: 인베이더스쿨 | E73: grimiartdesign | F73: 그리미아트 (디자인 성공비법, 디자인사업 코칭)
A74: 서재호 | B74: 사이클해커스 | E74: ramyloveboo
A75: 소영처럼 | B75: 아이비클래스 | E75: easy_design.ed | F75: 이지디자인.이디|상세페이지 제작 및 강의
A76: 연주 | B76: 타이탄클래스 | E76: runup.director | F76: 릴스PD 런디 | 브랜드를 위한 숏폼 콘텐츠 제작
A77: 프룻밀리언 | B77: 하버드클래스 | E77: s____haron | F77: (주)샤론컴퍼니 대표 김지은 | 모공밤 멀티밤 루티너 파이토신 ‘판매 1위’ | 파메스테틱 & 슈퍼젝션 입점교육🧡
A78: 배우는윤쇼 | B78: N잡연구소 | E78: bellnine59 | F78: 김종구
A79: 유튜브남매 | B79: 인베이더스쿨 | E79: daangn__easy | F79: 당근이지 | 사업가 | 컨설턴트 | 크리에이터
...

Sheet 사용방법
B1: 📘 사용방법 & 운영 가이드
B3: 탭별 역할
B4: 강사모집 | C4: 30명이 강사 후보 입력. M열(상태) + O열(등급) 관리
B5: 컨택관리 | C5: 발송 예정 이상 인원 옮겨서 차수별 발송 추적
B6: 현황판 | C6: 자동 집계 대시보드. 수정 불필요
B7: 0~3차메시지 | C7: 채널 규모별 A/B/C안 + 감정/의심 해결 가이드
B8: 연락금지 | C8: 금지 강사 목록. 추가 후 markBanned() 실행
B10: 상태값 기준 (M열)
B11: 미검토 | C11: 등록만 된 상태 (기본값)
B12: 컨펌 필요 | C12: 분류팀이 올림 → 본부장님 확인 필요
B13: 발송 예정 | C13: 본부장 컨펌 완료 → 컨택관리 탭에 옮기기
B14: 진행 중 | C14: 0차 이상 발송됨 → 컨택관리 탭에서 추적
B15: 계약 완료 | C15: 온보딩 완료 ✅
B16: 제외 | C16: 연락 불가 — N열에 사유 기재
B17: 보류 | C17: 지금은 아님 — 나중에 발송 예정으로 재진입 가능
B18: 거절 | C18: 명확한 거절 — 재연락 절대 금지
B20: 등급 기준 (O열)
B21: A | C21: 강의 이력 O + 수강생 성과 있음 → 1순위 | D21: 등급이 있어도 좋으나, 획일화가 되면 오히려 큰 의미가 없을 수 있겠다
B22: B | C22: 강의 이력 O + 성과 불명확 → 2순위 | D22: 일단 불러라 - 사짜, 최소기준 충족 못하다
B23: C | C23: 강의 이력 없음 + SNS/수익화 실적 있음 → 3순위 | D23: 트렌드(AI 유튜브 등) - 기준치 널널, 트렌드 X - 브랜딩, 소구점, 프로그램
B24: D | C24: 강의 이력 없음 + 실적 불명확 → 4순위
B26: 발송 타임라인
B27: D+0 0차 | C27: 첫 메시지 — DM 우선, 없으면 이메일
B28: D+3 1차 | C28: 리마인드 — 1차 팔로업 응답률 +49% (Belkins 1,100만건)
B29: D+6 2차 | C29: 증명 — 누적 응답 94% 도달
B30: D+9 3차 | C30: 브레이크업 — 무응답자만 선택 발송
B32: 채널 규모 기준 (메시지 탭 A/B/C안)
B33: A안 | C33: 소규모 — 팔로워/구독자 1만 미만
B34: B안 | C34: 중간 — 팔로워/구독자 1만~5만
B35: C안 | C35: 대형 — 팔로워/구독자 5만 이상
B37: 자주 쓰는 필터 (강사모집 탭)
B38: 컨펌 필요만 | C38: M열 → "컨펌 필요" (본부장님용)
B39: 발송 예정만 | C39: M열 → "발송 예정" (발송 담당자용)
B40: A등급만 | C40: O열 → "A" (우선순위 강사)
B41: 강의이력O만 | C41: F열 → "O"

Sheet 핏크닉메타
B1: 지원서_핏크닉메타 — 지원 응답
B2: 새 응답이 들어오면 L열이 노란색으로 표시돼요. 확인 후 드롭다운에서 상태를 바꾸세요.
A4: NO. | B4: 날짜 | C4: 이름 | D4: 강사명(활동명) | E4: 연락처 | F4: 강의경험 | G4: 온/오프라인 여부 | H4: 강사지원 계기, 동기, 자신의 장점 | I4: 강의 주제 서술 | J4: 경력과 수치적 성과 | K4: 수강생이 얻을 수 있는 것 | L4: 소셜미디어 | M4: 소셜미디어 링크 | N4: 담당자 검토여부
A5: NO. | B5: =IFERROR(__xludf.DUMMYFUNCTION("IMPORTRANGE(""https://docs.google.com/spreadsheets/d/1P6ZfKUnSFljb74LQnmtpD7ds-xKx-Mb9LdnpZNRIdeM"",""설문지 응답 시트1!A:l"")"),"#REF!") -> #REF! | N5: 검토상태
A6: {=IF(B6:B1001<>"", ROW(B6:B1001)-5, "")} | N6: 확인완료
N7: 확인완료
N8: 확인완료
N9: 확인완료
N10: 확인완료
N11: 확인완료
N12: 확인완료
N13: 확인완료
N14: 확인완료
N15: 확인완료
N16: 확인완료
N17: 확인완료
N18: 확인완료
... N88: 확인완료

Sheet 핏크닉홈
B1: 지원서_핏크닉홈페이지 — 지원 응답
B2: 새 응답이 들어오면 L열이 노란색으로 표시돼요. 확인 후 드롭다운에서 상태를 바꾸세요.
A4: NO. | B4: =IFERROR(__xludf.DUMMYFUNCTION("IMPORTRANGE(""https://docs.google.com/spreadsheets/d/1_UYbaZNAliPpV-l5VXoC5NxYjlvMjBYA6xLj5JtvaOM"",""설문지 응답 시트1!A:K"")"),"타임스탬프") -> 타임스탬프 | C4: =IFERROR(__xludf.DUMMYFUNCTION("""COMPUTED_VALUE"""),"이메일 주소") -> 이메일 주소 | D4: =IFERROR(__xludf.DUMMYFUNCTION("""COMPUTED_VALUE"""),"성함을 기입해주세요") -> 성함을 기입해주세요 | E4: =IFERROR(__xludf.DUMMYFUNCTION("""COMPUTED_VALUE"""),"활동명 및 닉네임을 기입해주세요") -> 활동명 및 닉네임을 기입해주세요 | F4: =IFERROR(__xludf.DUMMYFUNCTION("""COMPUTED_VALUE"""),"연락처를 적어주세요") -> 연락처를 적어주세요 | G4: =IFERROR(__xludf.DUMMYFUNCTION("""COMPUTED_VALUE"""),"다른 사이트 혹은 강의를 진행하신 경험이 있으신가요?") -> 다른 사이트 혹은 강의를 진행하신 경험이 있으신가요? | H4: =IFERROR(__xludf.DUMMYFUNCTION("""COMPUTED_VALUE"""),"강의하고 싶은 주제를 구체적으로 작성해주세요. 예시 1. 구매대행과 AI를 활용한 수익화 방법 2. 부동산 경매를 통해 돈을 버는 방법") -> 강의하고 싶은 주제를 구체적으로 작성해주세요. 예시 1. 구매대행과 AI를 활용한 수익화 방법 2. 부동산 경매를 통해 돈을 버는 방법 | I4: =IFERROR(__xludf.DUMMYFUNCTION("""COMPUTED_VALUE"""),"핏크닉 강사로 지원하신 동기 및 계기는 무엇인가요? 본인의 장점과 함께 자유롭게 작성해주세요. ") -> 핏크닉 강사로 지원하신 동기 및 계기는 무엇인가요? 본인의 장점과 함께 자유롭게 작성해주세요. | J4: =IFERROR(__xludf.DUMMYFUNCTION("""COMPUTED_VALUE"""),"경력과 어떤 성과를 만드셨는지 수치적으로 작성해주세요* 예시 1. 쿠팡을 통해 연매출 20억 달성 2. 부동산 경매로 순자산 30억 ") -> 경력과 어떤 성과를 만드셨는지 수치적으로 작성해주세요* 예시 1. 쿠팡을 통해 연매출 20억 달성 2. 부동산 경매로 순자산 30억 | K4: =IFERROR(__xludf.DUMMYFUNCTION("""COMPUTED_VALUE"""),"해당 분야에서 수강생의 성과를 만든 경험이 있다면 적어주세요. 1. 수강생이 부업으로 시작해 월 3천만 원 매출 달성 2. 부동산 경매를 알려줘 시세보다 1천만 원 싸게 구입") -> 해당 분야에서 수강생의 성과를 만든 경험이 있다면 적어주세요. 1. 수강생이 부업으로 시작해 월 3천만 원 매출 달성 2. 부동산 경매를 알려줘 시세보다 1천만 원 싸게 구입 | L4: =IFERROR(__xludf.DUMMYFUNCTION("""COMPUTED_VALUE"""),"해당 주제를 통해 수강생이 무엇을 얻을 수 있는지 구체적으로 작성해주세요. 예시 1. 쿠팡 부업을 통해 50만원 정도의 순이익 2. 경매를 통해, 시세보다 저렴하게 부동산 구입") -> 해당 주제를 통해 수강생이 무엇을 얻을 수 있는지 구체적으로 작성해주세요. 예시 1. 쿠팡 부업을 통해 50만원 정도의 순이익 2. 경매를 통해, 시세보다 저렴하게 부동산 구입 | M4: 검토상태
A5: {=IF(B5:B1000<>"", ROW(B5:B1000)-4, "")} -> 1 | B5: =IFERROR(__xludf.DUMMYFUNCTION("""COMPUTED_VALUE"""),45718.01939190972) -> 45718.019 | C5: =IFERROR(__xludf.DUMMYFUNCTION("""COMPUTED_VALUE"""),"") | D5: =IFERROR(__xludf.DUMMYFUNCTION("""COMPUTED_VALUE"""),"ss") -> ss | E5: =IFERROR(__xludf.DUMMYFUNCTION("""COMPUTED_VALUE"""),"ss") -> ss | G5: =IFERROR(__xludf.DUMMYFUNCTION("""COMPUTED_VALUE"""),"없음") -> 없음 | H5: =IFERROR(__xludf.DUMMYFUNCTION("""COMPUTED_VALUE"""),"ss") -> ss | I5: =IFERROR(__xludf.DUMMYFUNCTION("""COMPUTED_VALUE"""),"ss") -> ss | J5: =IFERROR(__xludf.DUMMYFUNCTION("""COMPUTED_VALUE"""),"ss") -> ss | L5: =IFERROR(__xludf.DUMMYFUNCTION("""COMPUTED_VALUE"""),"ss") -> ss | M5: 확인완료
A6: 2 | B6: =IFERROR(__xludf.DUMMYFUNCTION("""COMPUTED_VALUE"""),45722.021624375004) -> 45722.022 | C6: =IFERROR(__xludf.DUMMYFUNCTION("""COMPUTED_VALUE"""),"") | D6: =IFERROR(__xludf.DUMMYFUNCTION("""COMPUTED_VALUE"""),"박은주") -> 박은주 | E6: =IFERROR(__xludf.DUMMYFUNCTION("""COMPUTED_VALUE"""),"20년 연속 토익 990만점 강사") -> 20년 연속 토익 990만점 강사 | G6: =IFERROR(__xludf.DUMMYFUNCTION("""COMPUTED_VALUE"""),"없음") -> 없음 | H6: =IFERROR(__xludf.DUMMYFUNCTION("""COMPUTED_VALUE"""),"토익 시험 하루 전 3시간 특강으로 300점 올리기") -> 토익 시험 하루 전 3시간 특강으로 300점 올리기 | I6: =IFERROR(__xludf.DUMMYFUNCTION("""COMPUTED_VALUE"""),"성인대상 “부”를 증대시키는 노하우를 잘 알려주는 플랫폼으로 알고 가입을 했습니다. 성인들 중 이직이나 승진을 위해 토익 공부를 하는 사람도 많이 있으나 이들을 위한 단기 토익 / 초단기 토익 특강은 많지 않습니다. 단 하루 토익 정기 시험 전 3시간 특강을 통해 목표 점수에 도달하여 성공적인 승진 혹은 이직을 도울 수 있습니다. 제 강점은 20년 연속 토익 990만점을 받은 경력이 있으며 현재도 연세대학교 외국어학당에서 토익 수업을 하고 있는 토익 트"&"렌트를 누구보다 잘 알고 있는 사람이라 자부합니다. 그 동안 모아 온 기출 문제를 통해서 짧은 시간 최소의 시간을 투자하여 최대의 효율을 이룰 수 있게 도움을 줄 수 있습니다! ") -> 성인대상 “부”를 증대시키는 노하우를 잘 알려주는 플랫폼으로 알고 가입을 했습니다. 성인들 중 이직이나 승진을 위해 토익 공부를 하는 사람도 많이 있으나 이들을 위한 단기 토익 / 초단기 토익 특강은 많지 않습니다. 단 하루 토익 정기 시험 전 3시간 특강을 통해 목표 점수에 도달하여 성공적인 승진 혹은 이직을 도울 수 있습니다. 제 강점은 20년 연속 토익 990만점을 받은 경력이 있으며 현재도 연세대학교 외국어학당에서 토익 수업을 하고 있는 토익 트렌트를 누구보다 잘 알고 있는 사람이라 자부합니다. 그 동안 모아 온 기출 문제를 통해서 짧은 시간 최소의 시간을 투자하여 최대의 효율을 이룰 수 있게 도움을 줄 수 있습니다! | J6: =IFERROR(__xludf.DUMMYFUNCTION("""COMPUTED_VALUE"""),"1. 영어 왕기초 학생도 1달 공부하여 500넘기기 2. 토요일 정기 토익 시험 전 특강 듣고 985/970 편입에 필요한 성적 만들기") -> 1. 영어 왕기초 학생도 1달 공부하여 500넘기기 2. 토요일 정기 토익 시험 전 특강 듣고 985/970 편입에 필요한 성적 만들기 | K6: =IFERROR(__xludf.DUMMYFUNCTION("""COMPUTED_VALUE"""),"1. 위의 항목과 유사 (고득점 학생 다수 배출 및 정말 영어 왕기초 학생도 단기에 500 넘게 만듬)") -> 1. 위의 항목과 유사 (고득점 학생 다수 배출 및 정말 영어 왕기초 학생도 단기에 500 넘게 만듬) | L6: =IFERROR(__xludf.DUMMYFUNCTION("""COMPUTED_VALUE"""),"단 하루 3시간 특강으로 토익점수 300점 올리기") -> 단 하루 3시간 특강으로 토익점수 300점 올리기 | M6: 확인완료
A7: 3 | B7: =IFERROR(__xludf.DUMMYFUNCTION("""COMPUTED_VALUE"""),45728.67154998843) -> 45728.672 | C7: =IFERROR(__xludf.DUMMYFUNCTION("""COMPUTED_VALUE"""),"") | D7: =IFERROR(__xludf.DUMMYFUNCTION("""COMPUTED_VALUE"""),"손태훈") -> 손태훈 | E7: =IFERROR(__xludf.DUMMYFUNCTION("""COMPUTED_VALUE"""),"공간대여손PD") -> 공간대여손PD | G7: =IFERROR(__xludf.DUMMYFUNCTION("""COMPUTED_VALUE"""),"https://docs.google.com/forms/d/16D_xEWHRggpGhUtjzAt-N86lFZkti8RFV5DJ7OUN1Zg/edit") -> https://docs.google.com/forms/d/16D_xEWHRggpGhUtjzAt-N86lFZkti8RFV5DJ7OUN1Zg/edit | H7: =IFERROR(__xludf.DUMMYFUNCTION("""COMPUTED_VALUE"""),"가정집 공간대여를 통해 수익화 하는 방법 ") -> 가정집 공간대여를 통해 수익화 하는 방법 | I7: =IFERROR(__xludf.DUMMYFUNCTION("""COMPUTED_VALUE"""),"메일에 따로 후술하였습니다") -> 메일에 따로 후술하였습니다 | J7: =IFERROR(__xludf.DUMMYFUNCTION("""COMPUTED_VALUE"""),"가정집 원룸 하나로 월 200만원 고정 수익 달성, 이후 다양한 공간대여 사업 확장 중") -> 가정집 원룸 하나로 월 200만원 고정 수익 달성, 이후 다양한 공간대여 사업 확장 중 | K7: =IFERROR(__xludf.DUMMYFUNCTION("""COMPUTED_VALUE"""),"코칭 수강생 투자금 100만원으로 한달 10분 일하고 월 100만원 버는 부업 구조 완성 ") -> 코칭 수강생 투자금 100만원으로 한달 10분 일하고 월 100만원 버는 부업 구조 완성 | L7: =IFERROR(__xludf.DUMMYFUNCTION("""COMPUTED_VALUE"""),"공간대여 부업을 통해 50만원 정도의 순수익") -> 공간대여 부업을 통해 50만원 정도의 순수익 | M7: 확인완료
A8: 4 | B8: =IFERROR(__xludf.DUMMYFUNCTION("""COMPUTED_VALUE"""),45729.52381076389) -> 45729.524 | C8: =IFERROR(__xludf.DUMMYFUNCTION("""COMPUTED_VALUE"""),"") | D8: =IFERROR(__xludf.DUMMYFUNCTION("""COMPUTED_VALUE"""),"조명재") -> 조명재 | E8: =IFERROR(__xludf.DUMMYFUNCTION("""COMPUTED_VALUE"""),"셀링남") -> 셀링남 | G8: =IFERROR(__xludf.DUMMYFUNCTION("""COMPUTED_VALUE"""),"https://cyclehackers.com/product/283044/") -> https://cyclehackers.com/product/283044/ | H8: =IFERROR(__xludf.DUMMYFUNCTION("""COMPUTED_VALUE"""),"AI로 쉽고 편하게 월300버는 로켓그로스판매+건강기능식품위탁,제조강의") -> AI로 쉽고 편하게 월300버는 로켓그로스판매+건강기능식품위탁,제조강의 | I8: =IFERROR(__xludf.DUMMYFUNCTION("""COMPUTED_VALUE"""),"머니테이커 대표님과 미팅한번 해보고싶습니다 :)") -> 머니테이커 대표님과 미팅한번 해보고싶습니다 :) | J8: =IFERROR(__xludf.DUMMYFUNCTION("""COMPUTED_VALUE"""),"1.쿠팡플랫폼으로만 1제품으로 월2-3억 / 연매출100억") -> 1.쿠팡플랫폼으로만 1제품으로 월2-3억 / 연매출100억 | K8: =IFERROR(__xludf.DUMMYFUNCTION("""COMPUTED_VALUE"""),"(1)수강생이 부업이나 타강의성과없다가 월 1억달성 수강생,(2)하루강의듣고 집에서 실습 바로매출발생 https://cafe.naver.com/zed1254/1418") -> (1)수강생이 부업이나 타강의성과없다가 월 1억달성 수강생,(2)하루강의듣고 집에서 실습 바로매출발생 https://cafe.naver.com/zed1254/1418 | L8: =IFERROR(__xludf.DUMMYFUNCTION("""COMPUTED_VALUE"""),"1.쇼핑몰 A-Z 단체교육이더라도 1:1오픈채팅방을 개설하여 강사와 밀착코칭 초/중/고급 이해단계 및 수강생 경력이 각각 다르기때문 그래서 성과가 잘나오는 케이스") -> 1.쇼핑몰 A-Z 단체교육이더라도 1:1오픈채팅방을 개설하여 강사와 밀착코칭 초/중/고급 이해단계 및 수강생 경력이 각각 다르기때문 그래서 성과가 잘나오는 케이스 | M8: 확인완료
A9: 5 | B9: =IFERROR(__xludf.DUMMYFUNCTION("""COMPUTED_VALUE"""),45733.89746782408) -> 45733.897 | C9: =IFERROR(__xludf.DUMMYFUNCTION("""COMPUTED_VALUE"""),"") | D9: =IFERROR(__xludf.DUMMYFUNCTION("""COMPUTED_VALUE"""),"이아영") -> 이아영 | E9: =IFERROR(__xludf.DUMMYFUNCTION("""COMPUTED_VALUE"""),"설하") -> 설하 | G9: =IFERROR(__xludf.DUMMYFUNCTION("""COMPUTED_VALUE"""),"중고등 대상 입시 강의, 입시 컨설팅, 입시 설명회 등의 강의") -> 중고등 대상 입시 강의, 입시 컨설팅, 입시 설명회 등의 강의 | H9: =IFERROR(__xludf.DUMMYFUNCTION("""COMPUTED_VALUE"""),"경제 개괄, 부동산 경매 등") -> 경제 개괄, 부동산 경매 등 | I9: =IFERROR(__xludf.DUMMYFUNCTION("""COMPUTED_VALUE"""),"무료 수업 듣고 공부 진행하다가 흥미 생겨서") -> 무료 수업 듣고 공부 진행하다가 흥미 생겨서 | J9: =IFERROR(__xludf.DUMMYFUNCTION("""COMPUTED_VALUE"""),"아직 없습니다. 노동자산을 통한 확보만 진행했습니다..") -> 아직 없습니다. 노동자산을 통한 확보만 진행했습니다.. | L9: =IFERROR(__xludf.DUMMYFUNCTION("""COMPUTED_VALUE"""),"경제 흐름 및 기본 개념 파악, 부동산 기본 개념 파악 등") -> 경제 흐름 및 기본 개념 파악, 부동산 기본 개념 파악 등 | M9: 확인완료
